Workbook

Sheet Overview
A1: XYZ Demo Dashboards: Report Documentation
A2: Five Power BI dashboards built on fictional sample data for OAL (oilfield machining and fabrication). Data period Jan 2025 to Oct 2026. Amounts are in NGN. Figures were read from the dashboard screenshots; blue = typed from the dashboards, black = formula.
A4: Dashboards
A5: Sheet | B5: Page title | D5: Purpose | G5: Slicers | I5: Cards | J5: Charts and tables
A6: Sales | B6: Sales Performance | D6: Revenue, profit and orders by month, customer, service line, state and salesperson. | G6: Year, Service line, Customer | I6: =SUMIFS('Period Scope'!$D$21:$D$50,'Period Scope'!$A$21:$A$50,A6,'Period Scope'!$C$21:$C$50,"KPI cards") -> 6 | J6: =SUMIFS('Period Scope'!$D$21:$D$50,'Period Scope'!$A$21:$A$50,A6,'Period Scope'!$C$21:$C$50,"<>KPI cards") -> 5
A7: Production | B7: Production Dashboard | D7: Workshop job status, late delivery, backlog and hours efficiency. | G7: Year, Status | I7: =SUMIFS('Period Scope'!$D$21:$D$50,'Period Scope'!$A$21:$A$50,A7,'Period Scope'!$C$21:$C$50,"KPI cards") -> 6 | J7: =SUMIFS('Period Scope'!$D$21:$D$50,'Period Scope'!$A$21:$A$50,A7,'Period Scope'!$C$21:$C$50,"<>KPI cards") -> 5
A8: CRM | B8: CRM & Pipelines | D8: Quote pipeline, win rate, loss reasons and follow-ups. | G8: Year, Service line, Sales person, Stages | I8: =SUMIFS('Period Scope'!$D$21:$D$50,'Period Scope'!$A$21:$A$50,A8,'Period Scope'!$C$21:$C$50,"KPI cards") -> 5 | J8: =SUMIFS('Period Scope'!$D$21:$D$50,'Period Scope'!$A$21:$A$50,A8,'Period Scope'!$C$21:$C$50,"<>KPI cards") -> 5
A9: Finance | B9: Financial Dashboard | D9: Invoicing, collections, overdue balances, expenses and profit. | G9: Year, Customer | I9: =SUMIFS('Period Scope'!$D$21:$D$50,'Period Scope'!$A$21:$A$50,A9,'Period Scope'!$C$21:$C$50,"KPI cards") -> 6 | J9: =SUMIFS('Period Scope'!$D$21:$D$50,'Period Scope'!$A$21:$A$50,A9,'Period Scope'!$C$21:$C$50,"<>KPI cards") -> 5
A10: Inventory | B10: Inventory Dashboard | D10: Stock value, stock movement, days of inventory and reorder risks. | G10: Year, Vendor, Item description | I10: =SUMIFS('Period Scope'!$D$21:$D$50,'Period Scope'!$A$21:$A$50,A10,'Period Scope'!$C$21:$C$50,"KPI cards") -> 5 | J10: =SUMIFS('Period Scope'!$D$21:$D$50,'Period Scope'!$A$21:$A$50,A10,'Period Scope'!$C$21:$C$50,"<>KPI cards") -> 5
A12: How to read this workbook
A13: Period Scope: shows which charts are fixed to 2026 and which follow the Year slicer (and so show 2025 when it is selected).
A14: Sales, Production, CRM & Pipelines, Finance, Inventory: one sheet each with the KPIs explained, the visuals, the values read from each chart and the key insights.
A15: Checks: compares numbers that should agree across visuals and cards, and flags gaps.
A16: Open Items: fixes seen in the screenshots (check folder), with priority and status.
A17: Sample data: all names and figures are fictional and for demonstration only.

Sheet Period Scope
A1: Period Scope: which charts are fixed to 2026 and which follow the Year slicer
A3: Data covers Jan 2025 to Dec 2026. Each page has a Year slicer with All, 2025 and 2026.
A4: Fixed to 2026: six month-by-month trend charts carry a visual-level filter of Year = 2026 (the 2026 is in the title). They show Jan-Oct 2026/ Dec-2026 and are meant for quick decisions on the current year. Set Edit interactions to None for these charts so they stay on 2026 when the Year slicer changes; otherwise picking 2025 leaves them blank.
A5: Follows slicers: all KPI cards, bar charts, donuts, funnels and tables respond to every slicer on the page. With Year = All they cover both years; picking 2025 or 2026 re-filters them, so 2025 data is visible there whenever the slicer is used.
A6: The only 2026 chart that still shows 2025 is Sales 'Total Revenue and Revenue LY by Months (2026)': its Revenue LY line plots the previous year's values against the same 2026 months.
A7: Why this design: trend charts stay on the current year for fast reading, while cards and breakdowns stay flexible for year-on-year comparison.
A9: Summary
A10: Dashboard | B10: Charts fixed to 2026 | C10: Charts following slicers | D10: KPI cards | E10: Total visuals
A11: Sales | B11: =SUMIFS($D$21:$D$50,$A$21:$A$50,A11,$E$21:$E$50,"Fixed to 2026") -> 1 | C11: =SUMIFS($D$21:$D$50,$A$21:$A$50,A11,$E$21:$E$50,"Follows slicers",$C$21:$C$50,"<>KPI cards") -> 4 | D11: =SUMIFS($D$21:$D$50,$A$21:$A$50,A11,$C$21:$C$50,"KPI cards") -> 6 | E11: =SUM(B11:D11) -> 11
A12: Production | B12: =SUMIFS($D$21:$D$50,$A$21:$A$50,A12,$E$21:$E$50,"Fixed to 2026") -> 1 | C12: =SUMIFS($D$21:$D$50,$A$21:$A$50,A12,$E$21:$E$50,"Follows slicers",$C$21:$C$50,"<>KPI cards") -> 4 | D12: =SUMIFS($D$21:$D$50,$A$21:$A$50,A12,$C$21:$C$50,"KPI cards") -> 6 | E12: =SUM(B12:D12) -> 11
A13: CRM | B13: =SUMIFS($D$21:$D$50,$A$21:$A$50,A13,$E$21:$E$50,"Fixed to 2026") -> 1 | C13: =SUMIFS($D$21:$D$50,$A$21:$A$50,A13,$E$21:$E$50,"Follows slicers",$C$21:$C$50,"<>KPI cards") -> 4 | D13: =SUMIFS($D$21:$D$50,$A$21:$A$50,A13,$C$21:$C$50,"KPI cards") -> 5 | E13: =SUM(B13:D13) -> 10
A14: Finance | B14: =SUMIFS($D$21:$D$50,$A$21:$A$50,A14,$E$21:$E$50,"Fixed to 2026") -> 1 | C14: =SUMIFS($D$21:$D$50,$A$21:$A$50,A14,$E$21:$E$50,"Follows slicers",$C$21:$C$50,"<>KPI cards") -> 4 | D14: =SUMIFS($D$21:$D$50,$A$21:$A$50,A14,$C$21:$C$50,"KPI cards") -> 6 | E14: =SUM(B14:D14) -> 11
A15: Inventory | B15: =SUMIFS($D$21:$D$50,$A$21:$A$50,A15,$E$21:$E$50,"Fixed to 2026") -> 2 | C15: =SUMIFS($D$21:$D$50,$A$21:$A$50,A15,$E$21:$E$50,"Follows slicers",$C$21:$C$50,"<>KPI cards") -> 3 | D15: =SUMIFS($D$21:$D$50,$A$21:$A$50,A15,$C$21:$C$50,"KPI cards") -> 5 | E15: =SUM(B15:D15) -> 10
A16: Total | B16: =SUM(B11:B15) -> 6 | C16: =SUM(C11:C15) -> 19 | D16: =SUM(D11:D15) -> 28 | E16: =SUM(E11:E15) -> 53
A17: ="Only "&B16&" of "&(B16+C16)&" charts and tables are fixed to 2026. The other "&C16&" and all "&D16&" KPI cards follow the slicers, including Year." -> Only 6 of 25 charts and tables are fixed to 2026. The other 19 and all 28 KPI cards follow the slicers, including Year.
A19: Visual by visual
A20: Dashboard | B20: Visual | C20: Type | D20: Count | E20: Period setting | F20: Year slicer changes it? | G20: Other slicers it follows | H20: Notes
A21: Sales | B21: KPI cards | C21: KPI cards | D21: 6 | E21: Follows slicers | F21: =IF(E21="Fixed to 2026","No (fixed)","Yes") -> Yes | G21: Year, Service line, Customer | H21: Cards recalculate with every slicer.
A22: Sales | B22: Total Revenue and Revenue LY by Months (2026) | C22: Line chart | D22: 1 | E22: Fixed to 2026 | F22: =IF(E22="Fixed to 2026","No (fixed)","Yes") -> No (fixed) | G22: Service line, Customer | H22: Revenue LY line shows the same months of 2025.
A23: Sales | B23: Total Revenue by Customer Name | C23: Line chart | D23: 1 | E23: Follows slicers | F23: =IF(E23="Fixed to 2026","No (fixed)","Yes") -> Yes | G23: Year, Service line, Customer
A24: Sales | B24: Total Revenue by Service Line | C24: Column chart | D24: 1 | E24: Follows slicers | F24: =IF(E24="Fixed to 2026","No (fixed)","Yes") -> Yes | G24: Year, Service line, Customer
A25: Sales | B25: Total Revenue by State | C25: Column chart | D25: 1 | E25: Follows slicers | F25: =IF(E25="Fixed to 2026","No (fixed)","Yes") -> Yes | G25: Year, Service line, Customer
A26: Sales | B26: Sales Performance by Salesperson | C26: Table | D26: 1 | E26: Follows slicers | F26: =IF(E26="Fixed to 2026","No (fixed)","Yes") -> Yes | G26: Year, Service line, Customer
A27: Production | B27: KPI cards | C27: KPI cards | D27: 6 | E27: Follows slicers | F27: =IF(E27="Fixed to 2026","No (fixed)","Yes") -> Yes | G27: Year, Status | H27: Cards recalculate with every slicer.
A28: Production | B28: Completed Jobs by Months (2026) | C28: Column chart | D28: 1 | E28: Fixed to 2026 | F28: =IF(E28="Fixed to 2026","No (fixed)","Yes") -> No (fixed) | G28: Status | H28: Shows Jan-Sep 2026.
A29: Production | B29: Total Job Value by Supervisor | C29: Column chart | D29: 1 | E29: Follows slicers | F29: =IF(E29="Fixed to 2026","No (fixed)","Yes") -> Yes | G29: Year, Status
A30: Production | B30: Late Jobs by Service Line | C30: Funnel | D30: 1 | E30: Follows slicers | F30: =IF(E30="Fixed to 2026","No (fixed)","Yes") -> Yes | G30: Year, Status
A31: Production | B31: Late and Overdue Jobs (2025-2026) | C31: Table | D31: 1 | E31: Follows slicers | F31: =IF(E31="Fixed to 2026","No (fixed)","Yes") -> Yes | G31: Year, Status | H31: Title text is fixed; data follows the slicers.
A32: Production | B32: Total Job Value by Status | C32: Donut | D32: 1 | E32: Follows slicers | F32: =IF(E32="Fixed to 2026","No (fixed)","Yes") -> Yes | G32: Year, Status
A33: CRM | B33: KPI cards | C33: KPI cards | D33: 5 | E33: Follows slicers | F33: =IF(E33="Fixed to 2026","No (fixed)","Yes") -> Yes | G33: Year, Service line, Sales person, Stages | H33: Cards recalculate with every slicer.
A34: CRM | B34: Lost Quotes by Loss Reason | C34: Bar chart | D34: 1 | E34: Follows slicers | F34: =IF(E34="Fixed to 2026","No (fixed)","Yes") -> Yes | G34: Year, Service line, Sales person, Stages
A35: CRM | B35: Open Pipeline Value by Salesperson | C35: Bar chart | D35: 1 | E35: Follows slicers | F35: =IF(E35="Fixed to 2026","No (fixed)","Yes") -> Yes | G35: Year, Service line, Sales person, Stages
A36: CRM | B36: Total Quotes by Stage | C36: Funnel | D36: 1 | E36: Follows slicers | F36: =IF(E36="Fixed to 2026","No (fixed)","Yes") -> Yes | G36: Year, Service line, Sales person, Stages
A37: CRM | B37: Open Quotes: Follow-up List | C37: Table | D37: 1 | E37: Follows slicers | F37: =IF(E37="Fixed to 2026","No (fixed)","Yes") -> Yes | G37: Year, Service line, Sales person, Stages
A38: CRM | B38: Won Quotes and Lost Quotes by Months (2026) | C38: Stacked column | D38: 1 | E38: Fixed to 2026 | F38: =IF(E38="Fixed to 2026","No (fixed)","Yes") -> No (fixed) | G38: Service line, Sales person | H38: Shows Jan-Oct 2026.
A39: Finance | B39: KPI cards | C39: KPI cards | D39: 6 | E39: Follows slicers | F39: =IF(E39="Fixed to 2026","No (fixed)","Yes") -> Yes | G39: Year, Customer | H39: Cards recalculate with every slicer.
A40: Finance | B40: Total Revenue and Total Expenses by Months (2026) | C40: Line chart | D40: 1 | E40: Fixed to 2026 | F40: =IF(E40="Fixed to 2026","No (fixed)","Yes") -> No (fixed) | G40: Customer | H40: Shows Jan-Oct 2026.
A41: Finance | B41: Invoices by Status | C41: Donut | D41: 1 | E41: Follows slicers | F41: =IF(E41="Fixed to 2026","No (fixed)","Yes") -> Yes | G41: Year, Customer
A42: Finance | B42: Total Expenses by Category | C42: Bar chart | D42: 1 | E42: Follows slicers | F42: =IF(E42="Fixed to 2026","No (fixed)","Yes") -> Yes | G42: Year, Customer
A43: Finance | B43: Overdue Customers | C43: Table | D43: 1 | E43: Follows slicers | F43: =IF(E43="Fixed to 2026","No (fixed)","Yes") -> Yes | G43: Year, Customer
...

Sheet Sales
A1: Sales Performance Dashboard
A2: Values are as shown on the dashboard (blue = read from the dashboard, black = formula). Money is NGN; the dashboard still shows a $ symbol (see Open Items). Chart values in bn are rounded.
A4: KPIs on this dashboard
A5: KPI | B5: Value shown | C5: What it means | G5: How it is calculated
A6: Total Revenue | B6: 5 | C6: Income from products and services sold | G6: Sum of Sales[Revenue]
A7: Gross Profit | B7: 2 | C7: Revenue minus the cost of what was sold | G7: Total Revenue - Total Cost
A8: Total Orders | B8: 380 | C8: Number of sales orders | G8: Distinct count of OrderNo
A9: Avg Order Value | B9: 14 | C9: Average revenue per order | G9: Total Revenue / Total Orders
A10: Gross Margin % | B10: 0.36 | C10: Share of revenue kept after cost of sales | G10: Gross Profit / Total Revenue
A11: Active Customers | B11: 15 | C11: Customers with sales in the selection | G11: Distinct count of CustomerID
A13: Visuals and period behaviour
A14: Visual | B14: Type | C14: Period | E14: What it shows
A15: Total Revenue and Revenue LY by Months (2026) | B15: Line chart | C15: Fixed to 2026 | E15: Monthly revenue for Jan-Oct 2026 against the same months of 2025 (Revenue LY). The only chart that shows 2025 inside a 2026 view.
A16: Total Revenue by Customer Name | B16: Line chart | C16: Follows slicers | E16: Top 10 customers ranked by revenue.
A17: Total Revenue by Service Line | B17: Column chart | C17: Follows slicers | E17: Revenue split across the seven service lines.
A18: Total Revenue by State | B18: Column chart | C18: Follows slicers | E18: Revenue by client state.
A19: Sales Performance by Salesperson | B19: Table | C19: Follows slicers | E19: Revenue and gross margin % for each account manager.
A21: Sales Performance by Salesperson (₦M)
A22: Exact values from the dashboard table. The total is the revenue base used for the shares below.
A23: Salesperson | B23: Revenue (₦M) | C23: Gross margin % | D23: Share of revenue
A24: Chidi Okafor | B24: 1916.7726 | C24: 0.35 | D24: =B24/B28 -> 0.35002201
A25: Amaka Eze | B25: 1674.7243 | C25: 0.36 | D25: =B25/B28 -> 0.30582155
A26: Tunde Bakare | B26: 1047.5093 | C26: 0.36 | D26: =B26/B28 -> 0.19128576
A27: Ngozi Udoh | B27: 837.14257 | C27: 0.36 | D27: =B27/B28 -> 0.15287068
A28: Total | B28: =SUM(B24:B27) -> 5476.1488 | D28: =SUM(D24:D27) -> 1
A30: Revenue by Service Line (₦M)
A31: Read from chart labels (shown in bn, so rounded).
A32: Service line | B32: Revenue (₦M) | C32: Share
A33: Fabrication | B33: 1650 | C33: =B33/B40 -> 0.30054645
A34: Coating | B34: 1510 | C34: =B34/B40 -> 0.27504554
A35: Machining | B35: 830 | C35: =B35/B40 -> 0.15118397
A36: Spares & Procurement | B36: 550 | C36: =B36/B40 -> 0.10018215
A37: Pipe Thread Repair | B37: 480 | C37: =B37/B40 -> 0.087431694
A38: Fire & Gas | B38: 240 | C38: =B38/B40 -> 0.043715847
A39: Pigging | B39: 230 | C39: =B39/B40 -> 0.041894353
A40: Total | B40: =SUM(B33:B39) -> 5490 | C40: =SUM(C33:C39) -> 1
A42: Top 10 Customers by Revenue (₦M)
A43: Read from chart labels (shown in bn, so rounded). Share uses the salesperson total above.
A44: Customer | B44: Revenue ($M) | C44: Share of total revenue
A45: Delta Crude Services Ltd | B45: 1050 | C45: =B45/$B$28 -> 0.19174059
...

Sheet Production
A1: Production Dashboard
A2: Values are as shown on the dashboard (blue = read from the dashboard, black = formula). Money values in ₦M.
A4: KPIs on this dashboard
A5: KPI | B5: Value shown | C5: What it means | G5: How it is calculated
A6: Total Jobs | B6: 119 | C6: All workshop jobs in the selection | G6: Count of rows in Jobs
A7: Active Jobs | B7: 10 | C7: Jobs being worked on right now | G7: Jobs with status In Progress or In QC
A8: Late Jobs | B8: 41 | C8: Jobs delivered late or now past their due date | G8: Jobs with delivery status Late Delivery or Overdue
A9: On-Time Delivery % | B9: 0.65 | C9: Share of completed jobs delivered on or before the due date | G9: On-time completed jobs / completed jobs
A10: Backlog Value | B10: 200 | C10: Value of jobs not yet completed | G10: Job value where status is not Completed
A11: Hours Efficiency % | B11: 0.93 | C11: Budgeted hours compared with hours used on completed jobs | G11: Budgeted hours / actual hours (completed jobs). Below 100% means jobs used more hours than planned
A13: Visuals and period behaviour
A14: Visual | B14: Type | C14: Period | E14: What it shows
A15: Completed Jobs by Months (2026) | B15: Column chart | C15: Fixed to 2026 | E15: Jobs completed each month, Jan-Sep 2026.
A16: Total Job Value by Supervisor | B16: Column chart | C16: Follows slicers | E16: Job value handled by each supervisor.
A17: Late Jobs by Service Line | B17: Funnel | C17: Follows slicers | E17: Number of late jobs per service line.
A18: Late and Overdue Jobs (2025-2026) | B18: Table | C18: Follows slicers | E18: Jobs past their due date with days late. The title text is fixed; the data follows the slicers.
A19: Total Job Value by Status | B19: Donut | C19: Follows slicers | E19: Job value split by status (centre total 866M).
A21: Job Value by Status (₦M)
A22: Read from donut labels.
A23: Status | B23: Job value ($M) | C23: Share
A24: Completed | B24: 667 | C24: =B24/B28 -> 0.76931949
A25: Not Started | B25: 83 | C25: =B25/B28 -> 0.095732411
A26: On Hold | B26: 66 | C26: =B26/B28 -> 0.076124567
A27: In Progress | B27: 51 | C27: =B27/B28 -> 0.058823529
A28: Total | B28: =SUM(B24:B27) -> 867 | C28: =SUM(C24:C27) -> 1
A30: Job Value by Supervisor (₦M)
A31: Read from chart labels.
A32: Supervisor | B32: Job value ($M) | C32: Share
A33: Emeka Obi | B33: 276 | C33: =B33/B37 -> 0.31907514
A34: Femi Adeyemi | B34: 211 | C34: =B34/B37 -> 0.24393064
A35: Segun Alabi | B35: 196 | C35: =B35/B37 -> 0.2265896
A36: Bala Garba | B36: 182 | C36: =B36/B37 -> 0.21040462
A37: Total | B37: =SUM(B33:B36) -> 865 | C37: =SUM(C33:C36) -> 1
A39: Late Jobs by Service Line
A40: Read from funnel labels.
A41: Service line | B41: Late jobs | C41: Share of late jobs
A42: Machining | B42: 16 | C42: =B42/B48 -> 0.3902439
A43: Fire & Gas | B43: 9 | C43: =B43/B48 -> 0.2195122
A44: Fabrication | B44: 6 | C44: =B44/B48 -> 0.14634146
A45: Pigging | B45: 5 | C45: =B45/B48 -> 0.12195122
...

Sheet CRM
A1: CRM and Pipeline Dashboard
A2: Values are as shown on the dashboard (blue = read from the dashboard, black = formula). Values marked approx. were read from bar lengths.
A4: KPIs on this dashboard
A5: KPI | B5: Value shown | C5: What it means | G5: How it is calculated
A6: Open Pipeline Value | B6: 587 | C6: Value of quotes still open (Lead, Quoted, Negotiation) | G6: Sum of quote value for open stages
A7: Weighted Pipeline | B7: 232 | C7: Open pipeline adjusted by the win probability of each stage | G7: Quote value x stage probability (Lead 10%, Quoted 30%, Negotiation 60%)
A8: Win Rate % | B8: 0.56 | C8: Share of closed quotes that were won | G8: Won quotes / (Won + Lost)
A9: Avg Deal Size | B9: 7.5 | C9: Average value of a won quote | G9: Won value / number of won quotes
A10: Open Quotes | B10: 84 | C10: Quotes still open | G10: Count of quotes at Lead, Quoted or Negotiation
A12: Visuals and period behaviour
A13: Visual | B13: Type | C13: Period | E13: What it shows
A14: Lost Quotes by Loss Reason | B14: Bar chart | C14: Follows slicers | E14: Why quotes were lost.
A15: Open Pipeline Value by Salesperson | B15: Bar chart | C15: Follows slicers | E15: Open pipeline owned by each salesperson.
A16: Total Quotes by Stage | B16: Funnel | C16: Follows slicers | E16: Number of quotes at each stage, including Won and Lost.
A17: Open Quotes: Follow-up List | B17: Table | C17: Follows slicers | E17: Open quotes to chase, with customer, service line and stage.
A18: Won Quotes and Lost Quotes by Months (2026) | B18: Stacked column | C18: Fixed to 2026 | E18: Won and lost quotes each month, Jan-Oct 2026.
A20: Quotes by Stage
A21: Read from funnel labels.
A22: Stage | B22: Quotes | C22: Share
A23: Lead | B23: 10 | C23: =B23/B28 -> 0.027777778
A24: Quoted | B24: 40 | C24: =B24/B28 -> 0.11111111
A25: Negotiation | B25: 34 | C25: =B25/B28 -> 0.094444444
A26: Won | B26: 154 | C26: =B26/B28 -> 0.42777778
A27: Lost | B27: 122 | C27: =B27/B28 -> 0.33888889
A28: Total | B28: =SUM(B23:B27) -> 360 | C28: =SUM(C23:C27) -> 1
A30: Lost Quotes by Loss Reason (approx.)
A31: Approx.: read from bar lengths; the total matches the 122 lost quotes.
A32: Loss reason | B32: Lost quotes | C32: Share
A33: Lead time too long | B33: 32 | C33: =B33/B38 -> 0.26229508
A34: Project cancelled / postponed | B34: 26 | C34: =B34/B38 -> 0.21311475
A35: No response from client | B35: 25 | C35: =B35/B38 -> 0.20491803
A36: Lost to competitor | B36: 20 | C36: =B36/B38 -> 0.16393443
A37: Price too high | B37: 19 | C37: =B37/B38 -> 0.1557377
A38: Total | B38: =SUM(B33:B37) -> 122 | C38: =SUM(C33:C37) -> 1
A40: Open Pipeline Value by Salesperson (₦M, approx.)
A41: Approx.: read from bar lengths; the total matches the ₦587M card.
A42: Salesperson | B42: Open pipeline ($M) | C42: Share
A43: Chidi Okafor | B43: 189 | C43: =B43/B47 -> 0.32197615
A44: Tunde Bakare | B44: 182 | C44: =B44/B47 -> 0.31005111
A45: Amaka Eze | B45: 143 | C45: =B45/B47 -> 0.24361158
...

Sheet Finance
A1: Finance Dashboard
A2: Values are as shown on the dashboard (blue = read from the dashboard, black = formula). Money values in ₦M unless stated.
A4: KPIs on this dashboard
A5: KPI | B5: Value shown | C5: What it means | G5: How it is calculated
A6: Total Invoiced | B6: 5 | C6: Value of invoices issued | G6: Sum of Invoices[Invoice Amount]
A7: Total Collected | B7: 4.46 | C7: Cash received against invoices | G7: Sum of Invoices[Amount Paid]
A8: Outstanding Balance | B8: 894 | C8: Money customers still owe | G8: Sum of Invoices[Balance] (invoiced - paid)
A9: Overdue % | B9: 0.34 | C9: Share of the outstanding balance that is past its due date | G9: Overdue amount / outstanding balance
A10: Net Profit | B10: 909 | C10: Gross profit less operating expenses | G10: Gross Profit - Total Expenses
A11: Net Margin % | B11: 0.17 | C11: Net profit as a share of revenue | G11: Net Profit / Total Revenue
A13: Visuals and period behaviour
A14: Visual | B14: Type | C14: Period | E14: What it shows
A15: Total Revenue and Total Expenses by Months (2026) | B15: Line chart | C15: Fixed to 2026 | E15: Monthly revenue against expenses, Jan-Oct 2026.
A16: Invoices by Status | B16: Donut | C16: Follows slicers | E16: Invoiced value split into Paid, Open and Overdue.
A17: Total Expenses by Category | B17: Bar chart | C17: Follows slicers | E17: Operating expenses by category.
A18: Overdue Customers | B18: Table | C18: Follows slicers | E18: Customers with overdue invoices: invoice count, overdue amount and longest overdue days.
A19: Outstanding Balance by Ageing Bucket | B19: Column chart | C19: Follows slicers | E19: Outstanding balance by days overdue (Current, 1-30, 31-60, 90+).
A21: Invoiced Value by Status (₦M)
A22: Read from donut labels.
A23: Status | B23: Invoiced ($M) | C23: Share
A24: Paid | B24: 4189 | C24: =B24/B27 -> 0.78167569
A25: Open | B25: 589 | C25: =B25/B27 -> 0.10990857
A26: Overdue | B26: 581 | C26: =B26/B27 -> 0.10841575
A27: Total | B27: =SUM(B24:B26) -> 5359 | C27: =SUM(C24:C26) -> 1
A29: Outstanding Balance by Ageing Bucket (₦M)
A30: Read from chart labels. The 61-90 bucket has no balance, so it does not appear on the chart.
A31: Bucket | B31: Balance ($M) | C31: Share
A32: Current | B32: 589 | C32: =B32/B37 -> 0.65883669
A33: 1-30 | B33: 113 | C33: =B33/B37 -> 0.12639821
A34: 31-60 | B34: 8 | C34: =B34/B37 -> 0.0089485459
A35: 61-90 | B35: 0 | C35: =B35/B37 -> 0
A36: 90+ | B36: 184 | C36: =B36/B37 -> 0.20581655
A37: Total | B37: =SUM(B32:B36) -> 894 | C37: =SUM(C32:C36) -> 1
A39: Expenses by Category (₦M)
A40: Exact values from the chart labels.
A41: Category | B41: Expenses ($M) | C41: Share
A42: Payroll | B42: 525.248 | C42: =B42/B48 -> 0.50253781
A43: Admin & Overheads | B43: 146.815 | C43: =B43/B48 -> 0.14046715
A44: Utilities & Fuel | B44: 103.623 | C44: =B44/B48 -> 0.099142645
A45: Logistics & Transport | B45: 103.552 | C45: =B45/B48 -> 0.099074715
...

Sheet Inventory
A1: Inventory Dashboard
A2: Values are as shown on the dashboard (blue = read from the dashboard, black = formula). Money values in ₦M.
A4: KPIs on this dashboard
A5: KPI | B5: Value shown | C5: What it means | G5: How it is calculated
A6: Stock Value | B6: 79 | C6: Value of stock on hand at the end of the latest month | G6: Closing quantity x unit cost, latest month (not summed across months)
A7: Closing Stock Qty | B7: 594 | C7: Units in stock at the end of the latest month | G7: Closing quantity, latest month
A8: DIO | B8: 110 | C8: Days of Inventory Outstanding: how many days current stock lasts | G8: Average inventory value / cost of stock sales x days in the period
A9: Inventory Turnover | B9: 3.33 | C9: How many times stock is sold and replaced per year | G9: 365 / DIO
A10: Items Below Reorder | B10: 1 | C10: Stock items under their reorder level in the latest month | G10: Count of items where closing quantity < reorder level
A12: Visuals and period behaviour
A13: Visual | B13: Type | C13: Period | E13: What it shows
A14: Inbound Qty and Outbound Qty by Months (2026) | B14: Clustered column | C14: Fixed to 2026 | E14: Stock received against stock issued each month, Jan-Oct 2026.
A15: Stock Value by Months (2026) | B15: Line chart | C15: Fixed to 2026 | E15: Month-end stock value, Jan-Oct 2026.
A16: Items Below Reorder Level | B16: Table | C16: Follows slicers | E16: Items under their reorder level with vendor and closing quantity.
A17: Stock Value by Vendor | B17: Bar chart | C17: Follows slicers | E17: Where stock value sits by supplier.
A18: Stock Value by Item | B18: Bar chart | C18: Follows slicers | E18: Top 10 items by stock value.
A20: Stock Movement and Stock Value by Month, 2026
A21: Read from chart labels. Net movement = inbound - outbound; the total row sums the first three measures.
A22: Month | B22: Inbound qty | C22: Outbound qty | D22: Net movement | E22: Stock value ($M)
A23: Jan-2026 | B23: 0 | C23: 105 | D23: =B23-C23 -> -105 | E23: 73
A24: Feb-2026 | B24: 482 | C24: 406 | D24: =B24-C24 -> 76 | E24: 102
A25: Mar-2026 | B25: 39 | C25: 163 | D25: =B25-C25 -> -124 | E25: 93
A26: Apr-2026 | B26: 149 | C26: 128 | D26: =B26-C26 -> 21 | E26: 82
A27: May-2026 | B27: 128 | C27: 142 | D27: =B27-C27 -> -14 | E27: 84
A28: Jun-2026 | B28: 98 | C28: 109 | D28: =B28-C28 -> -11 | E28: 93
A29: Jul-2026 | B29: 234 | C29: 153 | D29: =B29-C29 -> 81 | E29: 103
A30: Aug-2026 | B30: 440 | C30: 477 | D30: =B30-C30 -> -37 | E30: 107
A31: Sep-2026 | B31: 262 | C31: 265 | D31: =B31-C31 -> -3 | E31: 88
A32: Oct-2026 | B32: 77 | C32: 240 | D32: =B32-C32 -> -163 | E32: 79
A33: Total | B33: =SUM(B23:B32) -> 1909 | C33: =SUM(C23:C32) -> 2188 | D33: =SUM(D23:D32) -> -279
A35: Stock Value by Vendor (₦M)
A36: Read from chart labels.
A37: Vendor | B37: Stock value ($M) | C37: Share
A38: SafeSense Detection Systems | B38: 22 | C38: =B38/B45 -> 0.27848101
A39: Hi Kalibre (Principal) | B39: 19 | C39: =B39/B45 -> 0.24050633
A40: Lagos Steel & Alloys | B40: 16 | C40: =B40/B45 -> 0.20253165
A41: Apapa Industrial Supplies | B41: 11 | C41: =B41/B45 -> 0.13924051
A42: Port Harcourt Bearings & Seals | B42: 7 | C42: =B42/B45 -> 0.088607595
A43: Weldtech Consumables | B43: 2 | C43: =B43/B45 -> 0.025316456
A44: Gulf Valve & Fittings | B44: 2 | C44: =B44/B45 -> 0.025316456
...

Sheet Checks
A1: Reconciliation Checks
A3: =COUNTIF(G6:G20,"Check")&" of "&COUNTA(G6:G20)&" checks flagged. Tolerance is relative (%) for amounts and absolute for rates." -> 0 of 15 checks flagged. Tolerance is relative (%) for amounts and absolute for rates.
A4: Blue tolerance values can be changed.
A5: Dashboard | B5: Check | C5: Value A | D5: Value B | E5: Difference | F5: Tolerance | G5: Status | H5: Comment
A6: Sales | B6: Salesperson total vs service line total ($M) | C6: =Sales!$B$28 -> 5476.1488 | D6: =Sales!$B$40 -> 5490 | E6: =C6-D6 -> -13.851198 | F6: 0.01 | G6: =IF(ABS(C6-D6)<=F6*MAX(ABS(C6),ABS(D6)),"OK","Check") -> OK | H6: Service line labels are rounded.
A7: Production | B7: Late jobs by service line vs Late Jobs card | C7: =Production!$B$48 -> 41 | D7: =Production!$B$8 -> 41 | E7: =C7-D7 -> 0 | F7: 0 | G7: =IF(ABS(C7-D7)<=F7,"OK","Check") -> OK
A8: Production | B8: Backlog card vs Not Started + On Hold + In Progress ($M) | C8: =Production!$B$10 -> 200 | D8: =SUM(Production!$B$25:$B$27) -> 200 | E8: =C8-D8 -> 0 | F8: 0 | G8: =IF(ABS(C8-D8)<=F8,"OK","Check") -> OK
A9: Production | B9: Job value by status vs by supervisor ($M) | C9: =Production!$B$28 -> 867 | D9: =Production!$B$37 -> 865 | E9: =C9-D9 -> 2 | F9: 0.01 | G9: =IF(ABS(C9-D9)<=F9*MAX(ABS(C9),ABS(D9)),"OK","Check") -> OK | H9: Rounded labels.
A10: CRM | B10: Open Quotes card vs Lead + Quoted + Negotiation | C10: =CRM!$B$10 -> 84 | D10: =SUM(CRM!$B$23:$B$25) -> 84 | E10: =C10-D10 -> 0 | F10: 0 | G10: =IF(ABS(C10-D10)<=F10,"OK","Check") -> OK
A11: CRM | B11: Win Rate card vs Won / (Won + Lost) | C11: =CRM!$B$8 -> 0.56 | D11: =CRM!$B$26/(CRM!$B$26+CRM!$B$27) -> 0.55797101 | E11: =C11-D11 -> 0.0020289855 | F11: 0.01 | G11: =IF(ABS(C11-D11)<=F11,"OK","Check") -> OK | H11: Card is rounded to whole %.
A12: CRM | B12: Loss reasons total vs Lost quotes in funnel (approx. values) | C12: =CRM!$B$38 -> 122 | D12: =CRM!$B$27 -> 122 | E12: =C12-D12 -> 0 | F12: 0.02 | G12: =IF(ABS(C12-D12)<=F12*MAX(ABS(C12),ABS(D12)),"OK","Check") -> OK | H12: Loss reasons read from bar lengths.
A13: CRM | B13: Pipeline by salesperson total vs Open Pipeline Value card ($M) | C13: =CRM!$B$47 -> 587 | D13: =CRM!$B$6 -> 587 | E13: =C13-D13 -> 0 | F13: 0.01 | G13: =IF(ABS(C13-D13)<=F13*MAX(ABS(C13),ABS(D13)),"OK","Check") -> OK | H13: Salesperson values read from bar lengths.
A14: Finance | B14: Ageing bucket total vs Outstanding Balance card ($M) | C14: =Finance!$B$37 -> 894 | D14: =Finance!$B$8 -> 894 | E14: =C14-D14 -> 0 | F14: 0.01 | G14: =IF(ABS(C14-D14)<=F14*MAX(ABS(C14),ABS(D14)),"OK","Check") -> OK
A15: Finance | B15: Invoiced (donut) less Collected vs Outstanding Balance ($M) | C15: =Finance!$B$27-Finance!$B$7*1000 -> 899 | D15: =Finance!$B$8 -> 894 | E15: =C15-D15 -> 5 | F15: 0.01 | G15: =IF(ABS(C15-D15)<=F15*MAX(ABS(C15),ABS(D15)),"OK","Check") -> OK | H15: Cards are rounded.
A16: Finance | B16: Overdue table total vs Overdue % x Outstanding Balance ($M) | C16: =Finance!$C$63 -> 303.80095 | D16: =Finance!$B$9*Finance!$B$8 -> 303.96 | E16: =C16-D16 -> -0.15905 | F16: 0.02 | G16: =IF(ABS(C16-D16)<=F16*MAX(ABS(C16),ABS(D16)),"OK","Check") -> OK | H16: Overdue % is rounded.
A17: Finance | B17: Net Profit / Revenue vs Net Margin % card | C17: =Finance!$B$10/Sales!$B$28 -> 0.16599257 | D17: =Finance!$B$11 -> 0.17 | E17: =C17-D17 -> -0.0040074324 | F17: 0.01 | G17: =IF(ABS(C17-D17)<=F17,"OK","Check") -> OK | H17: Revenue taken from the Sales sheet.
A18: Inventory | B18: Stock value by vendor total vs Stock Value card ($M) | C18: =Inventory!$B$45 -> 79 | D18: =Inventory!$B$6 -> 79 | E18: =C18-D18 -> 0 | F18: 0 | G18: =IF(ABS(C18-D18)<=F18,"OK","Check") -> OK
A19: Inventory | B19: Oct-2026 stock value (chart) vs Stock Value card ($M) | C19: =Inventory!$E$32 -> 79 | D19: =Inventory!$B$6 -> 79 | E19: =C19-D19 -> 0 | F19: 0 | G19: =IF(ABS(C19-D19)<=F19,"OK","Check") -> OK | H19: Card shows the latest month.
A20: Inventory | B20: 365 / DIO vs Inventory Turnover card | C20: =365/Inventory!$B$8 -> 3.3181818 | D20: =Inventory!$B$9 -> 3.33 | E20: =C20-D20 -> -0.011818182 | F20: 0.05 | G20: =IF(ABS(C20-D20)<=F20,"OK","Check") -> OK | H20: DIO and turnover use the same basis.
