Workbook

Sheet README
A1: OAL Demo Data - Sample Datasets for Power BI
A2: All names and figures are fictional sample data for demos. Amounts are in NGN. Period: Jan 2025 to Oct 2026.
A4: Sheets and the dashboard each one feeds
A5: Sheet | B5: Rows | C5: Feeds dashboard | D5: What it holds
A6: Customers | B6: =COUNTA(Customers!A2:A16) -> 15 | C6: Sales / CRM / Finance | D6: Client list with segment, state, account manager, payment terms
A7: Vendors | B7: =COUNTA(Vendors!A2:A8) -> 7 | C7: Inventory | D7: Suppliers, origin and lead time
A8: Items | B8: =COUNTA(Items!A2:A24) -> 23 | C8: Sales / Inventory | D8: Services and stock items with cost, price, service line, reorder level
A9: Sales | B9: =COUNTA(Sales!A2:A759) -> 758 | C9: Sales | D9: Order lines: revenue, cost, discount, gross profit
A10: Quotes | B10: =COUNTA(Quotes!A2:A361) -> 360 | C10: Customer and Pipeline (CRM) | D10: Quotes by stage, value, probability, weighted value, loss reason
A11: Stages | B11: =COUNTA(Stages!A2:A6) -> 5 | C11: Customer and Pipeline (CRM) | D11: Win probability per pipeline stage
A12: Jobs | B12: =COUNTA(Jobs!A2:A120) -> 119 | C12: Production Tracker | D12: Workshop jobs: status, due vs completion, hours, delivery status
A13: Inventory | B13: =COUNTA(Inventory!A2:A309) -> 308 | C13: Inventory | D13: Monthly stock movement and stock value per stock item
A14: Invoices | B14: =COUNTA(Invoices!A2:A371) -> 370 | C14: Finance | D14: Invoices with due date, payments, balance, ageing bucket
A15: Expenses | B15: =COUNTA(Expenses!A2:A155) -> 154 | C15: Finance | D15: Monthly operating expenses by category and cost centre
A17: Relationships to create in Power BI (many-to-one, single direction)
A18: Sales[CustomerID] -> Customers[CustomerID]
A19: Sales[ItemID] -> Items[ItemID]
A20: Quotes[CustomerID] -> Customers[CustomerID]
A21: Quotes[Stage] -> Stages[Stage]
A22: Jobs[CustomerID] -> Customers[CustomerID]
A23: Jobs[QuoteID] -> Quotes[QuoteID]
A24: Inventory[ItemID] -> Items[ItemID]
A25: Items[VendorID] -> Vendors[VendorID]
A26: Invoices[CustomerID] -> Customers[CustomerID]
A27: Invoices[OrderNo] -> Sales[OrderNo] (optional; OrderNo repeats in Sales, so leave out or use a bridge)
A29: Date table
... A33: Navy header = typed data. Purple header = calculated column (formula). The as-of date on the Settings sheet drives overdue, late and ageing logic.

Sheet Settings
A1: Setting | B1: Value
A2: As-of date (today for status calculations) | B2: 46320
A3: Currency | B3: NGN
A4: Change the as-of date to re-age invoices, jobs and quotes.

Sheet Customers
A1: CustomerID | B1: Customer Name | C1: Segment | D1: State | E1: Account Manager | F1: Payment Terms (Days) | G1: Customer Since
A2: C001 | B2: Delta Crude Services Ltd | C2: Oil & Gas Operator | D2: Delta | E2: Chidi Okafor | F2: 30 | G2: 2019
A3: C002 | B3: Niger Basin Petroleum | C3: Oil & Gas Operator | D3: Rivers | E3: Amaka Eze | F3: 45 | G3: 2018
A4: C003 | B4: Atlantic Offshore Marine | C4: Offshore Services | D4: Lagos | E4: Tunde Bakare | F4: 45 | G4: 2020
A5: C004 | B5: Eko Gas Processing Ltd | C5: Gas Processing | D5: Lagos | E5: Ngozi Udoh | F5: 30 | G5: 2021
A6: C005 | B6: Bonny Terminal Logistics | C6: Midstream | D6: Rivers | E6: Chidi Okafor | F6: 60 | G6: 2019
A7: C006 | B7: Calabar Energy Partners | C7: Oil & Gas Operator | D7: Akwa Ibom | E7: Amaka Eze | F7: 45 | G7: 2022
A8: C007 | B8: Warri Drilling Solutions | C8: Drilling Contractor | D8: Delta | E8: Tunde Bakare | F8: 30 | G8: 2020
A9: C008 | B9: Sapele Pipeline Works | C9: EPC Contractor | D9: Delta | E9: Ngozi Udoh | F9: 60 | G9: 2021
A10: C009 | B10: Harbour Point Engineering | C10: EPC Contractor | D10: Rivers | E10: Chidi Okafor | F10: 45 | G10: 2022
A11: C010 | B11: Okoro & Sons Oilfield Supplies | C11: Trading / Distributor | D11: Rivers | E11: Amaka Eze | F11: 30 | G11: 2023
A12: C011 | B12: Bayelsa Marginal Fields Ltd | C12: Oil & Gas Operator | D12: Bayelsa | E12: Tunde Bakare | F12: 60 | G12: 2023
A13: C012 | B13: Ibom Refining Co | C13: Refinery | D13: Akwa Ibom | E13: Ngozi Udoh | F13: 45 | G13: 2022
... A16: C015 | B16: Apex Wellhead Services | C16: Wellhead Services | D16: Rivers | E16: Tunde Bakare | F16: 30 | G16: 2024

Sheet Vendors
A1: VendorID | B1: Vendor Name | C1: Origin | D1: Lead Time (Days)
A2: V001 | B2: Hi Kalibre (Principal) | C2: Imported | D2: 45
A3: V002 | B3: Lagos Steel & Alloys | C3: Local | D3: 10
A4: V003 | B4: Apapa Industrial Supplies | C4: Local | D4: 7
A5: V004 | B5: Gulf Valve & Fittings | C5: Local | D5: 14
A6: V005 | B6: Weldtech Consumables | C6: Local | D6: 10
A7: V006 | B7: SafeSense Detection Systems | C7: Imported | D7: 60
A8: V007 | B8: Port Harcourt Bearings & Seals | C8: Local | D8: 10

Sheet Items
A1: ItemID | B1: Description | C1: Service Line | D1: Item Type | E1: Brand | F1: UOM | G1: Unit Cost | H1: Unit Price | I1: Reorder Level | J1: VendorID | K1: Margin %
A2: I101 | B2: Hi Kalibre Gate Valve 4" | C2: Spares & Procurement | D2: Stock | E2: Hi Kalibre | F2: Each | G2: 420000 | H2: 560000 | I2: 8 | J2: V001 | K2: =(H2-G2)/H2 -> 0.25
A3: I102 | B3: Hi Kalibre Ball Valve 2" | C3: Spares & Procurement | D3: Stock | E3: Hi Kalibre | F3: Each | G3: 180000 | H3: 250000 | I3: 15 | J3: V001 | K3: =(H3-G3)/H3 -> 0.28
A4: I103 | B4: Hi Kalibre Check Valve 6" | C4: Spares & Procurement | D4: Stock | E4: Hi Kalibre | F4: Each | G4: 610000 | H4: 820000 | I4: 6 | J4: V001 | K4: =(H4-G4)/H4 -> 0.25609756
A5: I104 | B5: Pressure Gauge 0-600 psi | C5: Spares & Procurement | D5: Stock | E5: Generic | F5: Each | G5: 45000 | H5: 68000 | I5: 25 | J5: V004 | K5: =(H5-G5)/H5 -> 0.33823529
A6: I105 | B6: Pipe Flange 6" 150# | C6: Spares & Procurement | D6: Stock | E6: Generic | F6: Each | G6: 95000 | H6: 135000 | I6: 30 | J6: V002 | K6: =(H6-G6)/H6 -> 0.2962963
A7: I106 | B7: Steel Pipe 6" Sch40 (6m) | C7: Spares & Procurement | D7: Stock | E7: Generic | F7: Length | G7: 380000 | H7: 480000 | I7: 20 | J7: V002 | K7: =(H7-G7)/H7 -> 0.20833333
A8: I107 | B8: Stud Bolt Set M20 | C8: Spares & Procurement | D8: Stock | E8: Generic | F8: Set | G8: 28000 | H8: 42000 | I8: 50 | J8: V003 | K8: =(H8-G8)/H8 -> 0.33333333
A9: I108 | B9: Gasket Kit (Spiral Wound) | C9: Spares & Procurement | D9: Stock | E9: Generic | F9: Kit | G9: 35000 | H9: 55000 | I9: 40 | J9: V003 | K9: =(H9-G9)/H9 -> 0.36363636
A10: I109 | B10: Hydraulic Hose Assembly | C10: Spares & Procurement | D10: Stock | E10: Generic | F10: Each | G10: 85000 | H10: 125000 | I10: 20 | J10: V003 | K10: =(H10-G10)/H10 -> 0.32
A11: I110 | B11: Heavy Duty Bearing Set | C11: Spares & Procurement | D11: Stock | E11: Generic | F11: Set | G11: 120000 | H11: 175000 | I11: 15 | J11: V007 | K11: =(H11-G11)/H11 -> 0.31428571
A12: I111 | B12: Welding Electrodes Box (E7018) | C12: Spares & Procurement | D12: Stock | E12: Generic | F12: Box | G12: 22000 | H12: 32000 | I12: 60 | J12: V005 | K12: =(H12-G12)/H12 -> 0.3125
A13: I112 | B13: Carbide Cutting Inserts Box | C13: Spares & Procurement | D13: Stock | E13: Generic | F13: Box | G13: 65000 | H13: 95000 | I13: 25 | J13: V005 | K13: =(H13-G13)/H13 -> 0.31578947
... A15: I114 | B15: Flame Detector UV/IR | C15: Fire & Gas | D15: Stock | E15: Generic | F15: Each | G15: 1100000 | H15: 1450000 | I15: 4 | J15: V006 | K15: =(H15-G15)/H15 -> 0.24137931
A16: I201 | B16: CNC Machining (per hour) | C16: Machining | D16: Service | E16: OAL Service | F16: Hour | G16: 28000 | H16: 45000 | K16: =(H16-G16)/H16 -> 0.37777778
A17: I202 | B17: Precision Turning Job | C17: Machining | D17: Service | E17: OAL Service | F17: Each | G17: 150000 | H17: 240000 | K17: =(H17-G17)/H17 -> 0.375
A18: I203 | B18: Pipe Thread Repair (per joint) | C18: Pipe Thread Repair | D18: Service | E18: OAL Service | F18: Joint | G18: 55000 | H18: 85000 | K18: =(H18-G18)/H18 -> 0.35294118
A19: I204 | B19: Tubing Thread Re-cut (per joint) | C19: Pipe Thread Repair | D19: Service | E19: OAL Service | F19: Joint | G19: 38000 | H19: 62000 | K19: =(H19-G19)/H19 -> 0.38709677
A20: I205 | B20: Fabrication - Skid Frame | C20: Fabrication | D20: Service | E20: OAL Service | F20: Each | G20: 2200000 | H20: 3500000 | K20: =(H20-G20)/H20 -> 0.37142857
A21: I206 | B21: Fabrication - Pressure Vessel | C21: Fabrication | D21: Service | E21: OAL Service | F21: Each | G21: 7800000 | H21: 12000000 | K21: =(H21-G21)/H21 -> 0.35
A22: I207 | B22: Pigging Service (per run) | C22: Pigging | D22: Service | E22: OAL Service | F22: Run | G22: 1700000 | H22: 2800000 | K22: =(H22-G22)/H22 -> 0.39285714
A23: I208 | B23: Epoxy Coating (per m2) | C23: Coating | D23: Service | E23: OAL Service | F23: m2 | G23: 11000 | H23: 18000 | K23: =(H23-G23)/H23 -> 0.38888889
A24: I209 | B24: Fire & Gas Detector Installation | C24: Fire & Gas | D24: Service | E24: OAL Service | F24: Each | G24: 400000 | H24: 650000 | K24: =(H24-G24)/H24 -> 0.38461538

Sheet Sales
A1: LineID | B1: OrderNo | C1: Order Date | D1: CustomerID | E1: Salesperson | F1: ItemID | G1: Service Line | H1: Quantity | I1: Unit Price | J1: Unit Cost | K1: Discount % | L1: Revenue | M1: Cost | N1: Gross Profit
A2: L00001 | B2: SO-2025-0001 | C2: 45662 | D2: C003 | E2: Tunde Bakare | F2: I205 | G2: =VLOOKUP(F2,Items!$A$2:$C$24,3,FALSE()) -> Fabrication | H2: 3 | I2: 3574300 | J2: 2209600 | K2: 0.02 | L2: =H2*I2*(1-K2) -> 10508442 | M2: =H2*J2 -> 6628800 | N2: =L2-M2 -> 3879642
A3: L00002 | B3: SO-2025-0001 | C3: 45662 | D3: C003 | E3: Tunde Bakare | F3: I104 | G3: =VLOOKUP(F3,Items!$A$2:$C$24,3,FALSE()) -> Spares & Procurement | H3: 17 | I3: 70800 | J3: 45700 | K3: 0 | L3: =H3*I3*(1-K3) -> 1203600 | M3: =H3*J3 -> 776900 | N3: =L3-M3 -> 426700
A4: L00003 | B4: SO-2025-0001 | C4: 45662 | D4: C003 | E4: Tunde Bakare | F4: I201 | G4: =VLOOKUP(F4,Items!$A$2:$C$24,3,FALSE()) -> Machining | H4: 282 | I4: 46900 | J4: 29100 | K4: 0 | L4: =H4*I4*(1-K4) -> 13225800 | M4: =H4*J4 -> 8206200 | N4: =L4-M4 -> 5019600
A5: L00004 | B5: SO-2025-0001 | C5: 45662 | D5: C003 | E5: Tunde Bakare | F5: I206 | G5: =VLOOKUP(F5,Items!$A$2:$C$24,3,FALSE()) -> Fabrication | H5: 2 | I5: 11740900 | J5: 8089500 | K5: 0 | L5: =H5*I5*(1-K5) -> 23481800 | M5: =H5*J5 -> 16179000 | N5: =L5-M5 -> 7302800
A6: L00005 | B6: SO-2025-0002 | C6: 45664 | D6: C002 | E6: Amaka Eze | F6: I101 | G6: =VLOOKUP(F6,Items!$A$2:$C$24,3,FALSE()) -> Spares & Procurement | H6: 2 | I6: 592800 | J6: 427000 | K6: 0.02 | L6: =H6*I6*(1-K6) -> 1161888 | M6: =H6*J6 -> 854000 | N6: =L6-M6 -> 307888
A7: L00006 | B7: SO-2025-0002 | C7: 45664 | D7: C002 | E7: Amaka Eze | F7: I201 | G7: =VLOOKUP(F7,Items!$A$2:$C$24,3,FALSE()) -> Machining | H7: 236 | I7: 45700 | J7: 27800 | K7: 0 | L7: =H7*I7*(1-K7) -> 10785200 | M7: =H7*J7 -> 6560800 | N7: =L7-M7 -> 4224400
A8: L00007 | B8: SO-2025-0002 | C8: 45664 | D8: C002 | E8: Amaka Eze | F8: I102 | G8: =VLOOKUP(F8,Items!$A$2:$C$24,3,FALSE()) -> Spares & Procurement | H8: 8 | I8: 247400 | J8: 185100 | K8: 0 | L8: =H8*I8*(1-K8) -> 1979200 | M8: =H8*J8 -> 1480800 | N8: =L8-M8 -> 498400
A9: L00008 | B9: SO-2025-0003 | C9: 45667 | D9: C004 | E9: Ngozi Udoh | F9: I113 | G9: =VLOOKUP(F9,Items!$A$2:$C$24,3,FALSE()) -> Fire & Gas | H9: 8 | I9: 707000 | J9: 524100 | K9: 0 | L9: =H9*I9*(1-K9) -> 5656000 | M9: =H9*J9 -> 4192800 | N9: =L9-M9 -> 1463200
A10: L00009 | B10: SO-2025-0003 | C10: 45667 | D10: C004 | E10: Ngozi Udoh | F10: I206 | G10: =VLOOKUP(F10,Items!$A$2:$C$24,3,FALSE()) -> Fabrication | H10: 2 | I10: 12301700 | J10: 7980600 | K10: 0 | L10: =H10*I10*(1-K10) -> 24603400 | M10: =H10*J10 -> 15961200 | N10: =L10-M10 -> 8642200
A11: L00010 | B11: SO-2025-0004 | C11: 45667 | D11: C009 | E11: Chidi Okafor | F11: I207 | G11: =VLOOKUP(F11,Items!$A$2:$C$24,3,FALSE()) -> Pigging | H11: 2 | I11: 2781300 | J11: 1691200 | K11: 0 | L11: =H11*I11*(1-K11) -> 5562600 | M11: =H11*J11 -> 3382400 | N11: =L11-M11 -> 2180200
A12: L00011 | B12: SO-2025-0004 | C12: 45667 | D12: C009 | E12: Chidi Okafor | F12: I204 | G12: =VLOOKUP(F12,Items!$A$2:$C$24,3,FALSE()) -> Pipe Thread Repair | H12: 180 | I12: 61500 | J12: 38200 | K12: 0 | L12: =H12*I12*(1-K12) -> 11070000 | M12: =H12*J12 -> 6876000 | N12: =L12-M12 -> 4194000
A13: L00012 | B13: SO-2025-0005 | C13: 45667 | D13: C002 | E13: Amaka Eze | F13: I207 | G13: =VLOOKUP(F13,Items!$A$2:$C$24,3,FALSE()) -> Pigging | H13: 1 | I13: 2754000 | J13: 1705100 | K13: 0 | L13: =H13*I13*(1-K13) -> 2754000 | M13: =H13*J13 -> 1705100 | N13: =L13-M13 -> 1048900
... A759: L00758 | B759: SO-2026-0380 | C759: 46319 | D759: C006 | E759: Amaka Eze | F759: I103 | G759: =VLOOKUP(F759,Items!$A$2:$C$24,3,FALSE()) -> Spares & Procurement | H759: 4 | I759: 832100 | J759: 603600 | K759: 0.05 | L759: =H759*I759*(1-K759) -> 3161980 | M759: =H759*J759 -> 2414400 | N759: =L759-M759 -> 747580

Sheet Quotes
A1: QuoteID | B1: Quote Date | C1: CustomerID | D1: Salesperson | E1: Service Line | F1: Description | G1: Stage | H1: Quote Value | I1: Probability | J1: Weighted Value | K1: Close Date (Actual or Expected) | L1: Loss Reason | M1: Age (Days)
A2: Q0001 | B2: 45660 | C2: C001 | D2: Chidi Okafor | E2: Fabrication | F2: Wellhead skid fabrication | G2: Won | H2: 1516000 | I2: =VLOOKUP(G2,Stages!$A$2:$B$6,2,FALSE()) -> 1 | J2: =H2*I2 -> 1516000 | K2: 45693 | M2: =IF(OR(G2="Won",G2="Lost"),K2-B2,Settings!$B$2-B2) -> 33
A3: Q0002 | B3: 45661 | C3: C004 | D3: Ngozi Udoh | E3: Fabrication | F3: Manifold fabrication | G3: Won | H3: 2235000 | I3: =VLOOKUP(G3,Stages!$A$2:$B$6,2,FALSE()) -> 1 | J3: =H3*I3 -> 2235000 | K3: 45720 | M3: =IF(OR(G3="Won",G3="Lost"),K3-B3,Settings!$B$2-B3) -> 59
A4: Q0003 | B4: 45663 | C4: C003 | D4: Tunde Bakare | E4: Spares & Procurement | F4: Spares package - rotating equipment | G4: Won | H4: 2029000 | I4: =VLOOKUP(G4,Stages!$A$2:$B$6,2,FALSE()) -> 1 | J4: =H4*I4 -> 2029000 | K4: 45726 | M4: =IF(OR(G4="Won",G4="Lost"),K4-B4,Settings!$B$2-B4) -> 63
A5: Q0004 | B5: 45664 | C5: C008 | D5: Ngozi Udoh | E5: Pigging | F5: Pipeline pigging run | G5: Lost | H5: 14683000 | I5: =VLOOKUP(G5,Stages!$A$2:$B$6,2,FALSE()) -> 0 | J5: =H5*I5 -> 0 | K5: 45725 | L5: Lead time too long | M5: =IF(OR(G5="Won",G5="Lost"),K5-B5,Settings!$B$2-B5) -> 61
A6: Q0005 | B6: 45667 | C6: C004 | D6: Ngozi Udoh | E6: Machining | F6: Custom flange machining | G6: Quoted | H6: 17124000 | I6: =VLOOKUP(G6,Stages!$A$2:$B$6,2,FALSE()) -> 0.3 | J6: =H6*I6 -> 5137200 | K6: 45716 | M6: =IF(OR(G6="Won",G6="Lost"),K6-B6,Settings!$B$2-B6) -> 653
A7: Q0006 | B7: 45674 | C7: C001 | D7: Chidi Okafor | E7: Pipe Thread Repair | F7: Casing thread inspection and repair | G7: Negotiation | H7: 16101000 | I7: =VLOOKUP(G7,Stages!$A$2:$B$6,2,FALSE()) -> 0.6 | J7: =H7*I7 -> 9660600 | K7: 45715 | M7: =IF(OR(G7="Won",G7="Lost"),K7-B7,Settings!$B$2-B7) -> 646
A8: Q0007 | B8: 45674 | C8: C001 | D8: Chidi Okafor | E8: Spares & Procurement | F8: Consumables supply | G8: Won | H8: 9271000 | I8: =VLOOKUP(G8,Stages!$A$2:$B$6,2,FALSE()) -> 1 | J8: =H8*I8 -> 9271000 | K8: 45698 | M8: =IF(OR(G8="Won",G8="Lost"),K8-B8,Settings!$B$2-B8) -> 24
A9: Q0008 | B9: 45677 | C9: C001 | D9: Chidi Okafor | E9: Machining | F9: Pump shaft re-machining | G9: Won | H9: 19080000 | I9: =VLOOKUP(G9,Stages!$A$2:$B$6,2,FALSE()) -> 1 | J9: =H9*I9 -> 19080000 | K9: 45691 | M9: =IF(OR(G9="Won",G9="Lost"),K9-B9,Settings!$B$2-B9) -> 14
A10: Q0009 | B10: 45678 | C10: C008 | D10: Ngozi Udoh | E10: Spares & Procurement | F10: Consumables supply | G10: Won | H10: 4986000 | I10: =VLOOKUP(G10,Stages!$A$2:$B$6,2,FALSE()) -> 1 | J10: =H10*I10 -> 4986000 | K10: 45695 | M10: =IF(OR(G10="Won",G10="Lost"),K10-B10,Settings!$B$2-B10) -> 17
A11: Q0010 | B11: 45678 | C11: C001 | D11: Chidi Okafor | E11: Fabrication | F11: Pressure vessel fabrication | G11: Won | H11: 7139000 | I11: =VLOOKUP(G11,Stages!$A$2:$B$6,2,FALSE()) -> 1 | J11: =H11*I11 -> 7139000 | K11: 45700 | M11: =IF(OR(G11="Won",G11="Lost"),K11-B11,Settings!$B$2-B11) -> 22
A12: Q0011 | B12: 45682 | C12: C006 | D12: Amaka Eze | E12: Machining | F12: Custom flange machining | G12: Won | H12: 8253000 | I12: =VLOOKUP(G12,Stages!$A$2:$B$6,2,FALSE()) -> 1 | J12: =H12*I12 -> 8253000 | K12: 45729 | M12: =IF(OR(G12="Won",G12="Lost"),K12-B12,Settings!$B$2-B12) -> 47
A13: Q0012 | B13: 45682 | C13: C003 | D13: Tunde Bakare | E13: Spares & Procurement | F13: Valve and fittings supply | G13: Quoted | H13: 6936000 | I13: =VLOOKUP(G13,Stages!$A$2:$B$6,2,FALSE()) -> 0.3 | J13: =H13*I13 -> 2080800 | K13: 45716 | M13: =IF(OR(G13="Won",G13="Lost"),K13-B13,Settings!$B$2-B13) -> 638
A14: Q0013 | B14: 45682 | C14: C009 | D14: Chidi Okafor | E14: Spares & Procurement | F14: Valve and fittings supply | G14: Lost | H14: 621000 | I14: =VLOOKUP(G14,Stages!$A$2:$B$6,2,FALSE()) -> 0 | J14: =H14*I14 -> 0 | K14: 45692 | L14: Lost to competitor | M14: =IF(OR(G14="Won",G14="Lost"),K14-B14,Settings!$B$2-B14) -> 10
A15: Q0014 | B15: 45687 | C15: C012 | D15: Ngozi Udoh | E15: Spares & Procurement | F15: Valve and fittings supply | G15: Lost | H15: 7099000 | I15: =VLOOKUP(G15,Stages!$A$2:$B$6,2,FALSE()) -> 0 | J15: =H15*I15 -> 0 | K15: 45740 | L15: Lost to competitor | M15: =IF(OR(G15="Won",G15="Lost"),K15-B15,Settings!$B$2-B15) -> 53
A16: Q0015 | B16: 45692 | C16: C001 | D16: Chidi Okafor | E16: Machining | F16: Pump shaft re-machining | G16: Won | H16: 19220000 | I16: =VLOOKUP(G16,Stages!$A$2:$B$6,2,FALSE()) -> 1 | J16: =H16*I16 -> 19220000 | K16: 45737 | M16: =IF(OR(G16="Won",G16="Lost"),K16-B16,Settings!$B$2-B16) -> 45
A17: Q0016 | B17: 45695 | C17: C001 | D17: Chidi Okafor | E17: Pipe Thread Repair | F17: Premium connection repair | G17: Won | H17: 3791000 | I17: =VLOOKUP(G17,Stages!$A$2:$B$6,2,FALSE()) -> 1 | J17: =H17*I17 -> 3791000 | K17: 45748 | M17: =IF(OR(G17="Won",G17="Lost"),K17-B17,Settings!$B$2-B17) -> 53
A18: Q0017 | B18: 45696 | C18: C002 | D18: Amaka Eze | E18: Pipe Thread Repair | F18: Premium connection repair | G18: Negotiation | H18: 2243000 | I18: =VLOOKUP(G18,Stages!$A$2:$B$6,2,FALSE()) -> 0.6 | J18: =H18*I18 -> 1345800 | K18: 45783 | M18: =IF(OR(G18="Won",G18="Lost"),K18-B18,Settings!$B$2-B18) -> 624
A19: Q0018 | B19: 45699 | C19: C012 | D19: Ngozi Udoh | E19: Fabrication | F19: Manifold fabrication | G19: Won | H19: 11073000 | I19: =VLOOKUP(G19,Stages!$A$2:$B$6,2,FALSE()) -> 1 | J19: =H19*I19 -> 11073000 | K19: 45734 | M19: =IF(OR(G19="Won",G19="Lost"),K19-B19,Settings!$B$2-B19) -> 35
A20: Q0019 | B20: 45700 | C20: C004 | D20: Ngozi Udoh | E20: Fire & Gas | F20: Flame detector replacement | G20: Won | H20: 2863000 | I20: =VLOOKUP(G20,Stages!$A$2:$B$6,2,FALSE()) -> 1 | J20: =H20*I20 -> 2863000 | K20: 45716 | M20: =IF(OR(G20="Won",G20="Lost"),K20-B20,Settings!$B$2-B20) -> 16
A21: Q0020 | B21: 45701 | C21: C012 | D21: Ngozi Udoh | E21: Spares & Procurement | F21: Flanges and pipe supply | G21: Won | H21: 14789000 | I21: =VLOOKUP(G21,Stages!$A$2:$B$6,2,FALSE()) -> 1 | J21: =H21*I21 -> 14789000 | K21: 45749 | M21: =IF(OR(G21="Won",G21="Lost"),K21-B21,Settings!$B$2-B21) -> 48
A22: Q0021 | B22: 45702 | C22: C001 | D22: Chidi Okafor | E22: Spares & Procurement | F22: Consumables supply | G22: Lost | H22: 1478000 | I22: =VLOOKUP(G22,Stages!$A$2:$B$6,2,FALSE()) -> 0 | J22: =H22*I22 -> 0 | K22: 45749 | L22: Lead time too long | M22: =IF(OR(G22="Won",G22="Lost"),K22-B22,Settings!$B$2-B22) -> 47
A23: Q0022 | B23: 45702 | C23: C003 | D23: Tunde Bakare | E23: Fire & Gas | F23: Fire and gas panel commissioning | G23: Negotiation | H23: 1797000 | I23: =VLOOKUP(G23,Stages!$A$2:$B$6,2,FALSE()) -> 0.6 | J23: =H23*I23 -> 1078200 | K23: 45739 | M23: =IF(OR(G23="Won",G23="Lost"),K23-B23,Settings!$B$2-B23) -> 618
A24: Q0023 | B24: 45705 | C24: C004 | D24: Ngozi Udoh | E24: Fabrication | F24: Pressure vessel fabrication | G24: Negotiation | H24: 13473000 | I24: =VLOOKUP(G24,Stages!$A$2:$B$6,2,FALSE()) -> 0.6 | J24: =H24*I24 -> 8083800 | K24: 45736 | M24: =IF(OR(G24="Won",G24="Lost"),K24-B24,Settings!$B$2-B24) -> 615
A25: Q0024 | B25: 45713 | C25: C003 | D25: Tunde Bakare | E25: Fire & Gas | F25: Flame detector replacement | G25: Won | H25: 6007000 | I25: =VLOOKUP(G25,Stages!$A$2:$B$6,2,FALSE()) -> 1 | J25: =H25*I25 -> 6007000 | K25: 45727 | M25: =IF(OR(G25="Won",G25="Lost"),K25-B25,Settings!$B$2-B25) -> 14
A26: Q0025 | B26: 45715 | C26: C008 | D26: Ngozi Udoh | E26: Spares & Procurement | F26: Consumables supply | G26: Quoted | H26: 1249000 | I26: =VLOOKUP(G26,Stages!$A$2:$B$6,2,FALSE()) -> 0.3 | J26: =H26*I26 -> 374700 | K26: 45776 | M26: =IF(OR(G26="Won",G26="Lost"),K26-B26,Settings!$B$2-B26) -> 605
A27: Q0026 | B27: 45717 | C27: C008 | D27: Ngozi Udoh | E27: Spares & Procurement | F27: Flanges and pipe supply | G27: Quoted | H27: 1674000 | I27: =VLOOKUP(G27,Stages!$A$2:$B$6,2,FALSE()) -> 0.3 | J27: =H27*I27 -> 502200 | K27: 45801 | M27: =IF(OR(G27="Won",G27="Lost"),K27-B27,Settings!$B$2-B27) -> 603
A28: Q0027 | B28: 45727 | C28: C003 | D28: Tunde Bakare | E28: Machining | F28: Valve body CNC machining | G28: Won | H28: 14881000 | I28: =VLOOKUP(G28,Stages!$A$2:$B$6,2,FALSE()) -> 1 | J28: =H28*I28 -> 14881000 | K28: 45793 | M28: =IF(OR(G28="Won",G28="Lost"),K28-B28,Settings!$B$2-B28) -> 66
A29: Q0028 | B29: 45734 | C29: C004 | D29: Ngozi Udoh | E29: Machining | F29: Wellhead component turning | G29: Lost | H29: 4772000 | I29: =VLOOKUP(G29,Stages!$A$2:$B$6,2,FALSE()) -> 0 | J29: =H29*I29 -> 0 | K29: 45787 | L29: No response from client | M29: =IF(OR(G29="Won",G29="Lost"),K29-B29,Settings!$B$2-B29) -> 53
A30: Q0029 | B30: 45734 | C30: C006 | D30: Amaka Eze | E30: Coating | F30: Pipe external coating | G30: Lost | H30: 14784000 | I30: =VLOOKUP(G30,Stages!$A$2:$B$6,2,FALSE()) -> 0 | J30: =H30*I30 -> 0 | K30: 45769 | L30: Lead time too long | M30: =IF(OR(G30="Won",G30="Lost"),K30-B30,Settings!$B$2-B30) -> 35
A31: Q0030 | B31: 45734 | C31: C005 | D31: Chidi Okafor | E31: Fabrication | F31: Wellhead skid fabrication | G31: Lost | H31: 8666000 | I31: =VLOOKUP(G31,Stages!$A$2:$B$6,2,FALSE()) -> 0 | J31: =H31*I31 -> 0 | K31: 45747 | L31: No response from client | M31: =IF(OR(G31="Won",G31="Lost"),K31-B31,Settings!$B$2-B31) -> 13
A32: Q0031 | B32: 45742 | C32: C001 | D32: Chidi Okafor | E32: Spares & Procurement | F32: Flanges and pipe supply | G32: Won | H32: 12204000 | I32: =VLOOKUP(G32,Stages!$A$2:$B$6,2,FALSE()) -> 1 | J32: =H32*I32 -> 12204000 | K32: 45758 | M32: =IF(OR(G32="Won",G32="Lost"),K32-B32,Settings!$B$2-B32) -> 16
A33: Q0032 | B33: 45744 | C33: C002 | D33: Amaka Eze | E33: Fabrication | F33: Pipe rack structure | G33: Won | H33: 6789000 | I33: =VLOOKUP(G33,Stages!$A$2:$B$6,2,FALSE()) -> 1 | J33: =H33*I33 -> 6789000 | K33: 45795 | M33: =IF(OR(G33="Won",G33="Lost"),K33-B33,Settings!$B$2-B33) -> 51
A34: Q0033 | B34: 45747 | C34: C005 | D34: Chidi Okafor | E34: Spares & Procurement | F34: Consumables supply | G34: Won | H34: 3095000 | I34: =VLOOKUP(G34,Stages!$A$2:$B$6,2,FALSE()) -> 1 | J34: =H34*I34 -> 3095000 | K34: 45758 | M34: =IF(OR(G34="Won",G34="Lost"),K34-B34,Settings!$B$2-B34) -> 11
A35: Q0034 | B35: 45748 | C35: C004 | D35: Ngozi Udoh | E35: Machining | F35: Wellhead component turning | G35: Won | H35: 5725000 | I35: =VLOOKUP(G35,Stages!$A$2:$B$6,2,FALSE()) -> 1 | J35: =H35*I35 -> 5725000 | K35: 45764 | M35: =IF(OR(G35="Won",G35="Lost"),K35-B35,Settings!$B$2-B35) -> 16
A36: Q0035 | B36: 45749 | C36: C001 | D36: Chidi Okafor | E36: Fire & Gas | F36: Gas detector installation | G36: Won | H36: 4966000 | I36: =VLOOKUP(G36,Stages!$A$2:$B$6,2,FALSE()) -> 1 | J36: =H36*I36 -> 4966000 | K36: 45780 | M36: =IF(OR(G36="Won",G36="Lost"),K36-B36,Settings!$B$2-B36) -> 31
A37: Q0036 | B37: 45756 | C37: C005 | D37: Chidi Okafor | E37: Fabrication | F37: Wellhead skid fabrication | G37: Lost | H37: 4729000 | I37: =VLOOKUP(G37,Stages!$A$2:$B$6,2,FALSE()) -> 0 | J37: =H37*I37 -> 0 | K37: 45816 | L37: No response from client | M37: =IF(OR(G37="Won",G37="Lost"),K37-B37,Settings!$B$2-B37) -> 60
A38: Q0037 | B38: 45761 | C38: C002 | D38: Amaka Eze | E38: Fabrication | F38: Wellhead skid fabrication | G38: Won | H38: 8718000 | I38: =VLOOKUP(G38,Stages!$A$2:$B$6,2,FALSE()) -> 1 | J38: =H38*I38 -> 8718000 | K38: 45810 | M38: =IF(OR(G38="Won",G38="Lost"),K38-B38,Settings!$B$2-B38) -> 49
A39: Q0038 | B39: 45761 | C39: C007 | D39: Tunde Bakare | E39: Coating | F39: Pipe external coating | G39: Lost | H39: 2176000 | I39: =VLOOKUP(G39,Stages!$A$2:$B$6,2,FALSE()) -> 0 | J39: =H39*I39 -> 0 | K39: 45804 | L39: Lead time too long | M39: =IF(OR(G39="Won",G39="Lost"),K39-B39,Settings!$B$2-B39) -> 43
A40: Q0039 | B40: 45762 | C40: C002 | D40: Amaka Eze | E40: Spares & Procurement | F40: Consumables supply | G40: Lost | H40: 1023000 | I40: =VLOOKUP(G40,Stages!$A$2:$B$6,2,FALSE()) -> 0 | J40: =H40*I40 -> 0 | K40: 45799 | L40: Lost to competitor | M40: =IF(OR(G40="Won",G40="Lost"),K40-B40,Settings!$B$2-B40) -> 37
...

Sheet Stages
A1: Stage | B1: Probability
A2: Lead | B2: 0.1
A3: Quoted | B3: 0.3
A4: Negotiation | B4: 0.6
A5: Won | B5: 1
A6: Lost | B6: 0

Sheet Jobs
A1: JobID | B1: QuoteID | C1: CustomerID | D1: Service Line | E1: Description | F1: Supervisor | G1: Start Date | H1: Due Date | I1: Completion Date | J1: Status | K1: Workshop Stage | L1: Job Value | M1: Budgeted Hours | N1: Actual Hours | O1: Hours Variance | P1: Days Late | Q1: Delivery Status
A2: J0001 | B2: Q0001 | C2: C001 | D2: Fabrication | E2: Wellhead skid fabrication | F2: Bala Garba | G2: 45700 | H2: 45803 | I2: 45807 | J2: Completed | K2: Dispatched | L2: 1516000 | M2: 27 | N2: 34 | O2: =N2-M2 -> 7 | P2: =IF(I2<>"",MAX(0,I2-H2),MAX(0,Settings!$B$2-H2)) -> 4 | Q2: =IF(J2="Completed",IF(I2<=H2,"On Time","Late Delivery"),IF(Settings!$B$2>H2,"Overdue","On Track")) -> Late Delivery
A3: J0002 | B3: Q0002 | C3: C004 | D3: Fabrication | E3: Manifold fabrication | F3: Bala Garba | G3: 45726 | H3: 45799 | I3: 45788 | J3: Completed | K3: Dispatched | L3: 2235000 | M3: 40 | N3: 36 | O3: =N3-M3 -> -4 | P3: =IF(I3<>"",MAX(0,I3-H3),MAX(0,Settings!$B$2-H3)) -> 0 | Q3: =IF(J3="Completed",IF(I3<=H3,"On Time","Late Delivery"),IF(Settings!$B$2>H3,"Overdue","On Track")) -> On Time
A4: J0003 | B4: Q0008 | C4: C001 | D4: Machining | E4: Pump shaft re-machining | F4: Emeka Obi | G4: 45700 | H4: 45716 | I4: 45713 | J4: Completed | K4: Dispatched | L4: 19080000 | M4: 346 | N4: 311 | O4: =N4-M4 -> -35 | P4: =IF(I4<>"",MAX(0,I4-H4),MAX(0,Settings!$B$2-H4)) -> 0 | Q4: =IF(J4="Completed",IF(I4<=H4,"On Time","Late Delivery"),IF(Settings!$B$2>H4,"Overdue","On Track")) -> On Time
A5: J0004 | B5: Q0010 | C5: C001 | D5: Fabrication | E5: Pressure vessel fabrication | F5: Femi Adeyemi | G5: 45710 | H5: 45831 | I5: 45830 | J5: Completed | K5: Dispatched | L5: 7139000 | M5: 129 | N5: 111 | O5: =N5-M5 -> -18 | P5: =IF(I5<>"",MAX(0,I5-H5),MAX(0,Settings!$B$2-H5)) -> 0 | Q5: =IF(J5="Completed",IF(I5<=H5,"On Time","Late Delivery"),IF(Settings!$B$2>H5,"Overdue","On Track")) -> On Time
A6: J0005 | B6: Q0011 | C6: C006 | D6: Machining | E6: Custom flange machining | F6: Bala Garba | G6: 45734 | H6: 45754 | I6: 45760 | J6: Completed | K6: Dispatched | L6: 8253000 | M6: 150 | N6: 156 | O6: =N6-M6 -> 6 | P6: =IF(I6<>"",MAX(0,I6-H6),MAX(0,Settings!$B$2-H6)) -> 6 | Q6: =IF(J6="Completed",IF(I6<=H6,"On Time","Late Delivery"),IF(Settings!$B$2>H6,"Overdue","On Track")) -> Late Delivery
A7: J0006 | B7: Q0015 | C7: C001 | D7: Machining | E7: Pump shaft re-machining | F7: Femi Adeyemi | G7: 45747 | H7: 45770 | I7: 45769 | J7: Completed | K7: Dispatched | L7: 19220000 | M7: 349 | N7: 406 | O7: =N7-M7 -> 57 | P7: =IF(I7<>"",MAX(0,I7-H7),MAX(0,Settings!$B$2-H7)) -> 0 | Q7: =IF(J7="Completed",IF(I7<=H7,"On Time","Late Delivery"),IF(Settings!$B$2>H7,"Overdue","On Track")) -> On Time
A8: J0007 | B8: Q0016 | C8: C001 | D8: Pipe Thread Repair | E8: Premium connection repair | F8: Emeka Obi | G8: 45758 | H8: 45781 | I8: 45774 | J8: Completed | K8: Dispatched | L8: 3791000 | M8: 68 | N8: 58 | O8: =N8-M8 -> -10 | P8: =IF(I8<>"",MAX(0,I8-H8),MAX(0,Settings!$B$2-H8)) -> 0 | Q8: =IF(J8="Completed",IF(I8<=H8,"On Time","Late Delivery"),IF(Settings!$B$2>H8,"Overdue","On Track")) -> On Time
A9: J0008 | B9: Q0018 | C9: C012 | D9: Fabrication | E9: Manifold fabrication | F9: Bala Garba | G9: 45739 | H9: 45791 | I9: 45791 | J9: Completed | K9: Dispatched | L9: 11073000 | M9: 201 | N9: 174 | O9: =N9-M9 -> -27 | P9: =IF(I9<>"",MAX(0,I9-H9),MAX(0,Settings!$B$2-H9)) -> 0 | Q9: =IF(J9="Completed",IF(I9<=H9,"On Time","Late Delivery"),IF(Settings!$B$2>H9,"Overdue","On Track")) -> On Time
A10: J0009 | B10: Q0019 | C10: C004 | D10: Fire & Gas | E10: Flame detector replacement | F10: Femi Adeyemi | G10: 45727 | H10: 45751 | I10: 45752 | J10: Completed | K10: Dispatched | L10: 2863000 | M10: 52 | N10: 65 | O10: =N10-M10 -> 13 | P10: =IF(I10<>"",MAX(0,I10-H10),MAX(0,Settings!$B$2-H10)) -> 1 | Q10: =IF(J10="Completed",IF(I10<=H10,"On Time","Late Delivery"),IF(Settings!$B$2>H10,"Overdue","On Track")) -> Late Delivery
A11: J0010 | B11: Q0024 | C11: C003 | D11: Fire & Gas | E11: Flame detector replacement | F11: Bala Garba | G11: 45739 | H11: 45772 | I11: 45765 | J11: Completed | K11: Dispatched | L11: 6007000 | M11: 109 | N11: 113 | O11: =N11-M11 -> 4 | P11: =IF(I11<>"",MAX(0,I11-H11),MAX(0,Settings!$B$2-H11)) -> 0 | Q11: =IF(J11="Completed",IF(I11<=H11,"On Time","Late Delivery"),IF(Settings!$B$2>H11,"Overdue","On Track")) -> On Time
A12: J0011 | B12: Q0027 | C12: C003 | D12: Machining | E12: Valve body CNC machining | F12: Emeka Obi | G12: 45800 | H12: 45820 | I12: 45820 | J12: Completed | K12: Dispatched | L12: 14881000 | M12: 270 | N12: 255 | O12: =N12-M12 -> -15 | P12: =IF(I12<>"",MAX(0,I12-H12),MAX(0,Settings!$B$2-H12)) -> 0 | Q12: =IF(J12="Completed",IF(I12<=H12,"On Time","Late Delivery"),IF(Settings!$B$2>H12,"Overdue","On Track")) -> On Time
A13: J0012 | B13: Q0032 | C13: C002 | D13: Fabrication | E13: Pipe rack structure | F13: Emeka Obi | G13: 45801 | H13: 45896 | I13: 45894 | J13: Completed | K13: Dispatched | L13: 6789000 | M13: 123 | N13: 146 | O13: =N13-M13 -> 23 | P13: =IF(I13<>"",MAX(0,I13-H13),MAX(0,Settings!$B$2-H13)) -> 0 | Q13: =IF(J13="Completed",IF(I13<=H13,"On Time","Late Delivery"),IF(Settings!$B$2>H13,"Overdue","On Track")) -> On Time
... A20: J0019 | B20: Q0047 | C20: C011 | D20: Pipe Thread Repair | E20: Tubing thread repair | F20: Segun Alabi | G20: 45852 | H20: 45873 | I20: 45876 | J20: Completed | K20: Dispatched | L20: 6371000 | M20: 115 | N20: 114 | O20: =N20-M20 -> -1 | P20: =IF(I20<>"",MAX(0,I20-H20),MAX(0,Settings!$B$2-H20)) -> 3 | Q20: =IF(J20="Completed",IF(I20<=H20,"On Time","Late Delivery"),IF(Settings!$B$2>H20,"Overdue","On Track")) -> Late Delivery
A21: J0020 | B21: Q0052 | C21: C005 | D21: Pipe Thread Repair | E21: Casing thread inspection and repair | F21: Emeka Obi | G21: 45817 | H21: 45838 | J21: On Hold | K21: - | L21: 994000 | M21: 20 | N21: 22 | O21: =N21-M21 -> 2 | P21: =IF(I21<>"",MAX(0,I21-H21),MAX(0,Settings!$B$2-H21)) -> 482 | Q21: =IF(J21="Completed",IF(I21<=H21,"On Time","Late Delivery"),IF(Settings!$B$2>H21,"Overdue","On Track")) -> Overdue
A22: J0021 | B22: Q0053 | C22: C004 | D22: Fabrication | E22: Wellhead skid fabrication | F22: Bala Garba | G22: 45806 | H22: 45903 | I22: 45900 | J22: Completed | K22: Dispatched | L22: 52105000 | M22: 947 | N22: 1020 | O22: =N22-M22 -> 73 | P22: =IF(I22<>"",MAX(0,I22-H22),MAX(0,Settings!$B$2-H22)) -> 0 | Q22: =IF(J22="Completed",IF(I22<=H22,"On Time","Late Delivery"),IF(Settings!$B$2>H22,"Overdue","On Track")) -> On Time
A23: J0022 | B23: Q0069 | C23: C002 | D23: Machining | E23: Custom flange machining | F23: Segun Alabi | G23: 45884 | H23: 45923 | I23: 45922 | J23: Completed | K23: Dispatched | L23: 3481000 | M23: 63 | N23: 58 | O23: =N23-M23 -> -5 | P23: =IF(I23<>"",MAX(0,I23-H23),MAX(0,Settings!$B$2-H23)) -> 0 | Q23: =IF(J23="Completed",IF(I23<=H23,"On Time","Late Delivery"),IF(Settings!$B$2>H23,"Overdue","On Track")) -> On Time
A24: J0023 | B24: Q0071 | C24: C002 | D24: Coating | E24: Structural steel coating | F24: Bala Garba | G24: 45886 | H24: 45946 | I24: 45943 | J24: Completed | K24: Dispatched | L24: 3766000 | M24: 68 | N24: 80 | O24: =N24-M24 -> 12 | P24: =IF(I24<>"",MAX(0,I24-H24),MAX(0,Settings!$B$2-H24)) -> 0 | Q24: =IF(J24="Completed",IF(I24<=H24,"On Time","Late Delivery"),IF(Settings!$B$2>H24,"Overdue","On Track")) -> On Time
A25: J0024 | B25: Q0072 | C25: C001 | D25: Machining | E25: Valve body CNC machining | F25: Femi Adeyemi | G25: 45867 | H25: 45891 | I25: 45894 | J25: Completed | K25: Dispatched | L25: 4796000 | M25: 87 | N25: 94 | O25: =N25-M25 -> 7 | P25: =IF(I25<>"",MAX(0,I25-H25),MAX(0,Settings!$B$2-H25)) -> 3 | Q25: =IF(J25="Completed",IF(I25<=H25,"On Time","Late Delivery"),IF(Settings!$B$2>H25,"Overdue","On Track")) -> Late Delivery
A26: J0025 | B26: Q0075 | C26: C004 | D26: Pipe Thread Repair | E26: Tubing thread repair | F26: Segun Alabi | G26: 45897 | H26: 45911 | I26: 45918 | J26: Completed | K26: Dispatched | L26: 10008000 | M26: 181 | N26: 183 | O26: =N26-M26 -> 2 | P26: =IF(I26<>"",MAX(0,I26-H26),MAX(0,Settings!$B$2-H26)) -> 7 | Q26: =IF(J26="Completed",IF(I26<=H26,"On Time","Late Delivery"),IF(Settings!$B$2>H26,"Overdue","On Track")) -> Late Delivery
A27: J0026 | B27: Q0078 | C27: C001 | D27: Fire & Gas | E27: Gas detector installation | F27: Segun Alabi | G27: 45852 | H27: 45890 | I27: 45893 | J27: Completed | K27: Dispatched | L27: 3643000 | M27: 66 | N27: 85 | O27: =N27-M27 -> 19 | P27: =IF(I27<>"",MAX(0,I27-H27),MAX(0,Settings!$B$2-H27)) -> 3 | Q27: =IF(J27="Completed",IF(I27<=H27,"On Time","Late Delivery"),IF(Settings!$B$2>H27,"Overdue","On Track")) -> Late Delivery
A28: J0027 | B28: Q0084 | C28: C003 | D28: Fabrication | E28: Pressure vessel fabrication | F28: Emeka Obi | G28: 45887 | H28: 45933 | I28: 45931 | J28: Completed | K28: Dispatched | L28: 1274000 | M28: 23 | N28: 29 | O28: =N28-M28 -> 6 | P28: =IF(I28<>"",MAX(0,I28-H28),MAX(0,Settings!$B$2-H28)) -> 0 | Q28: =IF(J28="Completed",IF(I28<=H28,"On Time","Late Delivery"),IF(Settings!$B$2>H28,"Overdue","On Track")) -> On Time
A29: J0028 | B29: Q0090 | C29: C001 | D29: Machining | E29: Wellhead component turning | F29: Femi Adeyemi | G29: 45875 | H29: 45896 | I29: 45896 | J29: Completed | K29: Dispatched | L29: 1701000 | M29: 30 | N29: 26 | O29: =N29-M29 -> -4 | P29: =IF(I29<>"",MAX(0,I29-H29),MAX(0,Settings!$B$2-H29)) -> 0 | Q29: =IF(J29="Completed",IF(I29<=H29,"On Time","Late Delivery"),IF(Settings!$B$2>H29,"Overdue","On Track")) -> On Time
A30: J0029 | B30: Q0091 | C30: C006 | D30: Pigging | E30: Pipeline pigging run | F30: Segun Alabi | G30: 45903 | H30: 45910 | I30: 45911 | J30: Completed | K30: Dispatched | L30: 3229000 | M30: 58 | N30: 68 | O30: =N30-M30 -> 10 | P30: =IF(I30<>"",MAX(0,I30-H30),MAX(0,Settings!$B$2-H30)) -> 1 | Q30: =IF(J30="Completed",IF(I30<=H30,"On Time","Late Delivery"),IF(Settings!$B$2>H30,"Overdue","On Track")) -> Late Delivery
A31: J0030 | B31: Q0092 | C31: C001 | D31: Fire & Gas | E31: Fire and gas panel commissioning | F31: Segun Alabi | G31: 45877 | H31: 45921 | J31: On Hold | K31: - | L31: 2173000 | M31: 39 | N31: 44 | O31: =N31-M31 -> 5 | P31: =IF(I31<>"",MAX(0,I31-H31),MAX(0,Settings!$B$2-H31)) -> 399 | Q31: =IF(J31="Completed",IF(I31<=H31,"On Time","Late Delivery"),IF(Settings!$B$2>H31,"Overdue","On Track")) -> Overdue
A32: J0031 | B32: Q0106 | C32: C002 | D32: Fire & Gas | E32: Flame detector replacement | F32: Segun Alabi | G32: 45912 | H32: 45934 | J32: On Hold | K32: - | L32: 4723000 | M32: 85 | N32: 101 | O32: =N32-M32 -> 16 | P32: =IF(I32<>"",MAX(0,I32-H32),MAX(0,Settings!$B$2-H32)) -> 386 | Q32: =IF(J32="Completed",IF(I32<=H32,"On Time","Late Delivery"),IF(Settings!$B$2>H32,"Overdue","On Track")) -> Overdue
A33: J0032 | B33: Q0108 | C33: C015 | D33: Fabrication | E33: Chemical injection skid | F33: Bala Garba | G33: 45963 | H33: 46054 | I33: 46046 | J33: Completed | K33: Dispatched | L33: 6790000 | M33: 123 | N33: 155 | O33: =N33-M33 -> 32 | P33: =IF(I33<>"",MAX(0,I33-H33),MAX(0,Settings!$B$2-H33)) -> 0 | Q33: =IF(J33="Completed",IF(I33<=H33,"On Time","Late Delivery"),IF(Settings!$B$2>H33,"Overdue","On Track")) -> On Time
A34: J0033 | B34: Q0112 | C34: C001 | D34: Machining | E34: Wellhead component turning | F34: Femi Adeyemi | G34: 45969 | H34: 46007 | I34: 46010 | J34: Completed | K34: Dispatched | L34: 2221000 | M34: 40 | N34: 45 | O34: =N34-M34 -> 5 | P34: =IF(I34<>"",MAX(0,I34-H34),MAX(0,Settings!$B$2-H34)) -> 3 | Q34: =IF(J34="Completed",IF(I34<=H34,"On Time","Late Delivery"),IF(Settings!$B$2>H34,"Overdue","On Track")) -> Late Delivery
A35: J0034 | B35: Q0117 | C35: C008 | D35: Fabrication | E35: Pressure vessel fabrication | F35: Emeka Obi | G35: 45987 | H35: 46042 | I35: 46037 | J35: Completed | K35: Dispatched | L35: 1913000 | M35: 34 | N35: 42 | O35: =N35-M35 -> 8 | P35: =IF(I35<>"",MAX(0,I35-H35),MAX(0,Settings!$B$2-H35)) -> 0 | Q35: =IF(J35="Completed",IF(I35<=H35,"On Time","Late Delivery"),IF(Settings!$B$2>H35,"Overdue","On Track")) -> On Time
A36: J0035 | B36: Q0118 | C36: C003 | D36: Fabrication | E36: Chemical injection skid | F36: Emeka Obi | G36: 45988 | H36: 46115 | I36: 46113 | J36: Completed | K36: Dispatched | L36: 1638000 | M36: 29 | N36: 35 | O36: =N36-M36 -> 6 | P36: =IF(I36<>"",MAX(0,I36-H36),MAX(0,Settings!$B$2-H36)) -> 0 | Q36: =IF(J36="Completed",IF(I36<=H36,"On Time","Late Delivery"),IF(Settings!$B$2>H36,"Overdue","On Track")) -> On Time
A37: J0036 | B37: Q0119 | C37: C010 | D37: Fire & Gas | E37: Flame detector replacement | F37: Segun Alabi | G37: 45995 | H37: 46015 | I37: 46015 | J37: Completed | K37: Dispatched | L37: 1214000 | M37: 22 | N37: 19 | O37: =N37-M37 -> -3 | P37: =IF(I37<>"",MAX(0,I37-H37),MAX(0,Settings!$B$2-H37)) -> 0 | Q37: =IF(J37="Completed",IF(I37<=H37,"On Time","Late Delivery"),IF(Settings!$B$2>H37,"Overdue","On Track")) -> On Time
A38: J0037 | B38: Q0124 | C38: C006 | D38: Machining | E38: Gearbox housing machining | F38: Segun Alabi | G38: 45967 | H38: 45987 | I38: 45988 | J38: Completed | K38: Dispatched | L38: 9518000 | M38: 173 | N38: 184 | O38: =N38-M38 -> 11 | P38: =IF(I38<>"",MAX(0,I38-H38),MAX(0,Settings!$B$2-H38)) -> 1 | Q38: =IF(J38="Completed",IF(I38<=H38,"On Time","Late Delivery"),IF(Settings!$B$2>H38,"Overdue","On Track")) -> Late Delivery
A39: J0038 | B39: Q0128 | C39: C009 | D39: Machining | E39: Pump shaft re-machining | F39: Segun Alabi | G39: 45980 | H39: 46000 | I39: 46006 | J39: Completed | K39: Dispatched | L39: 15330000 | M39: 278 | N39: 286 | O39: =N39-M39 -> 8 | P39: =IF(I39<>"",MAX(0,I39-H39),MAX(0,Settings!$B$2-H39)) -> 6 | Q39: =IF(J39="Completed",IF(I39<=H39,"On Time","Late Delivery"),IF(Settings!$B$2>H39,"Overdue","On Track")) -> Late Delivery
A40: J0039 | B40: Q0133 | C40: C001 | D40: Machining | E40: Gearbox housing machining | F40: Segun Alabi | G40: 45967 | H40: 46007 | I40: 46011 | J40: Completed | K40: Dispatched | L40: 4395000 | M40: 79 | N40: 78 | O40: =N40-M40 -> -1 | P40: =IF(I40<>"",MAX(0,I40-H40),MAX(0,Settings!$B$2-H40)) -> 4 | Q40: =IF(J40="Completed",IF(I40<=H40,"On Time","Late Delivery"),IF(Settings!$B$2>H40,"Overdue","On Track")) -> Late Delivery
A41: J0040 | B41: Q0135 | C41: C001 | D41: Pigging | E41: Intelligent pigging support | F41: Segun Alabi | G41: 45982 | H41: 45999 | I41: 46000 | J41: Completed | K41: Dispatched | L41: 1258000 | M41: 22 | N41: 24 | O41: =N41-M41 -> 2 | P41: =IF(I41<>"",MAX(0,I41-H41),MAX(0,Settings!$B$2-H41)) -> 1 | Q41: =IF(J41="Completed",IF(I41<=H41,"On Time","Late Delivery"),IF(Settings!$B$2>H41,"Overdue","On Track")) -> Late Delivery
A42: J0041 | B42: Q0136 | C42: C004 | D42: Fabrication | E42: Manifold fabrication | F42: Segun Alabi | G42: 46002 | H42: 46128 | I42: 46129 | J42: Completed | K42: Dispatched | L42: 2525000 | M42: 45 | N42: 50 | O42: =N42-M42 -> 5 | P42: =IF(I42<>"",MAX(0,I42-H42),MAX(0,Settings!$B$2-H42)) -> 1 | Q42: =IF(J42="Completed",IF(I42<=H42,"On Time","Late Delivery"),IF(Settings!$B$2>H42,"Overdue","On Track")) -> Late Delivery
A43: J0042 | B43: Q0137 | C43: C008 | D43: Fire & Gas | E43: Flame detector replacement | F43: Emeka Obi | G43: 46003 | H43: 46040 | I43: 46041 | J43: Completed | K43: Dispatched | L43: 7176000 | M43: 130 | N43: 123 | O43: =N43-M43 -> -7 | P43: =IF(I43<>"",MAX(0,I43-H43),MAX(0,Settings!$B$2-H43)) -> 1 | Q43: =IF(J43="Completed",IF(I43<=H43,"On Time","Late Delivery"),IF(Settings!$B$2>H43,"Overdue","On Track")) -> Late Delivery
A44: J0043 | B44: Q0141 | C44: C008 | D44: Pigging | E44: Pig launcher/receiver servicing | F44: Emeka Obi | G44: 45979 | H44: 45991 | I44: 45989 | J44: Completed | K44: Dispatched | L44: 8219000 | M44: 149 | N44: 169 | O44: =N44-M44 -> 20 | P44: =IF(I44<>"",MAX(0,I44-H44),MAX(0,Settings!$B$2-H44)) -> 0 | Q44: =IF(J44="Completed",IF(I44<=H44,"On Time","Late Delivery"),IF(Settings!$B$2>H44,"Overdue","On Track")) -> On Time
... A51: J0050 | B51: Q0160 | C51: C005 | D51: Machining | E51: Valve body CNC machining | F51: Segun Alabi | G51: 46023 | H51: 46047 | I51: 46049 | J51: Completed | K51: Dispatched | L51: 1969000 | M51: 35 | N51: 35 | O51: =N51-M51 -> 0 | P51: =IF(I51<>"",MAX(0,I51-H51),MAX(0,Settings!$B$2-H51)) -> 2 | Q51: =IF(J51="Completed",IF(I51<=H51,"On Time","Late Delivery"),IF(Settings!$B$2>H51,"Overdue","On Track")) -> Late Delivery
A52: J0051 | B52: Q0161 | C52: C011 | D52: Fire & Gas | E52: Fire and gas panel commissioning | F52: Bala Garba | G52: 46048 | H52: 46062 | J52: On Hold | K52: - | L52: 8482000 | M52: 154 | N52: 182 | O52: =N52-M52 -> 28 | P52: =IF(I52<>"",MAX(0,I52-H52),MAX(0,Settings!$B$2-H52)) -> 258 | Q52: =IF(J52="Completed",IF(I52<=H52,"On Time","Late Delivery"),IF(Settings!$B$2>H52,"Overdue","On Track")) -> Overdue
...

Sheet Inventory
A1: Month | B1: ItemID | C1: Opening Qty | D1: Inbound Qty | E1: Outbound Qty | F1: Closing Qty | G1: Unit Cost | H1: Stock Value | I1: Below Reorder Level?
A2: 45658 | B2: I101 | C2: 16 | D2: 0 | E2: 2 | F2: =C2+D2-E2 -> 14 | G2: 420000 | H2: =F2*G2 -> 5880000 | I2: =IF(F2<VLOOKUP(B2,Items!$A$2:$I$24,9,FALSE()),"Yes","No") -> No
A3: 45689 | B3: I101 | C3: 14 | D3: 0 | E3: 0 | F3: =C3+D3-E3 -> 14 | G3: 420000 | H3: =F3*G3 -> 5880000 | I3: =IF(F3<VLOOKUP(B3,Items!$A$2:$I$24,9,FALSE()),"Yes","No") -> No
A4: 45717 | B4: I101 | C4: 14 | D4: 0 | E4: 0 | F4: =C4+D4-E4 -> 14 | G4: 420000 | H4: =F4*G4 -> 5880000 | I4: =IF(F4<VLOOKUP(B4,Items!$A$2:$I$24,9,FALSE()),"Yes","No") -> No
A5: 45748 | B5: I101 | C5: 14 | D5: 0 | E5: 0 | F5: =C5+D5-E5 -> 14 | G5: 420000 | H5: =F5*G5 -> 5880000 | I5: =IF(F5<VLOOKUP(B5,Items!$A$2:$I$24,9,FALSE()),"Yes","No") -> No
A6: 45778 | B6: I101 | C6: 14 | D6: 0 | E6: 4 | F6: =C6+D6-E6 -> 10 | G6: 420000 | H6: =F6*G6 -> 4200000 | I6: =IF(F6<VLOOKUP(B6,Items!$A$2:$I$24,9,FALSE()),"Yes","No") -> No
A7: 45809 | B7: I101 | C7: 10 | D7: 0 | E7: 3 | F7: =C7+D7-E7 -> 7 | G7: 420000 | H7: =F7*G7 -> 2940000 | I7: =IF(F7<VLOOKUP(B7,Items!$A$2:$I$24,9,FALSE()),"Yes","No") -> Yes
A8: 45839 | B8: I101 | C8: 7 | D8: 0 | E8: 2 | F8: =C8+D8-E8 -> 5 | G8: 420000 | H8: =F8*G8 -> 2100000 | I8: =IF(F8<VLOOKUP(B8,Items!$A$2:$I$24,9,FALSE()),"Yes","No") -> Yes
A9: 45870 | B9: I101 | C9: 5 | D9: 21 | E9: 2 | F9: =C9+D9-E9 -> 24 | G9: 420000 | H9: =F9*G9 -> 10080000 | I9: =IF(F9<VLOOKUP(B9,Items!$A$2:$I$24,9,FALSE()),"Yes","No") -> No
A10: 45901 | B10: I101 | C10: 24 | D10: 0 | E10: 0 | F10: =C10+D10-E10 -> 24 | G10: 420000 | H10: =F10*G10 -> 10080000 | I10: =IF(F10<VLOOKUP(B10,Items!$A$2:$I$24,9,FALSE()),"Yes","No") -> No
A11: 45931 | B11: I101 | C11: 24 | D11: 0 | E11: 0 | F11: =C11+D11-E11 -> 24 | G11: 420000 | H11: =F11*G11 -> 10080000 | I11: =IF(F11<VLOOKUP(B11,Items!$A$2:$I$24,9,FALSE()),"Yes","No") -> No
A12: 45962 | B12: I101 | C12: 24 | D12: 0 | E12: 5 | F12: =C12+D12-E12 -> 19 | G12: 420000 | H12: =F12*G12 -> 7980000 | I12: =IF(F12<VLOOKUP(B12,Items!$A$2:$I$24,9,FALSE()),"Yes","No") -> No
A13: 45992 | B13: I101 | C13: 19 | D13: 8 | E13: 0 | F13: =C13+D13-E13 -> 27 | G13: 420000 | H13: =F13*G13 -> 11340000 | I13: =IF(F13<VLOOKUP(B13,Items!$A$2:$I$24,9,FALSE()),"Yes","No") -> No
... A309: 46296 | B309: I114 | C309: 10 | D309: 10 | E309: 8 | F309: =C309+D309-E309 -> 12 | G309: 1100000 | H309: =F309*G309 -> 13200000 | I309: =IF(F309<VLOOKUP(B309,Items!$A$2:$I$24,9,FALSE()),"Yes","No") -> No

Sheet Invoices
A1: InvoiceID | B1: OrderNo | C1: Invoice Date | D1: CustomerID | E1: Invoice Amount | F1: Payment Terms (Days) | G1: Due Date | H1: Payment Date | I1: Amount Paid | J1: Balance | K1: Status | L1: Days Overdue | M1: Ageing Bucket
A2: INV-00001 | B2: SO-2025-0001 | C2: 45675 | D2: C003 | E2: =SUMIFS(Sales!$L$2:$L$759,Sales!$B$2:$B$759,B2) -> 48419642 | F2: 45 | G2: =C2+F2 -> 45720 | H2: 45745 | I2: 48419642 | J2: =ROUND(E2-I2,0) -> 0 | K2: =IF(J2<=0,"Paid",IF(G2<Settings!$B$2,"Overdue","Open")) -> Paid | L2: =IF(J2>0,MAX(0,Settings!$B$2-G2),0) -> 0 | M2: =IF(J2<=0,"Paid",IF(L2=0,"Current",IF(L2<=30,"1-30",IF(L2<=60,"31-60",IF(L2<=90,"61-90","90+"))))) -> Paid
A3: INV-00002 | B3: SO-2025-0002 | C3: 45668 | D3: C002 | E3: =SUMIFS(Sales!$L$2:$L$759,Sales!$B$2:$B$759,B3) -> 13926288 | F3: 45 | G3: =C3+F3 -> 45713 | H3: 45732 | I3: 13926288 | J3: =ROUND(E3-I3,0) -> 0 | K3: =IF(J3<=0,"Paid",IF(G3<Settings!$B$2,"Overdue","Open")) -> Paid | L3: =IF(J3>0,MAX(0,Settings!$B$2-G3),0) -> 0 | M3: =IF(J3<=0,"Paid",IF(L3=0,"Current",IF(L3<=30,"1-30",IF(L3<=60,"31-60",IF(L3<=90,"61-90","90+"))))) -> Paid
A4: INV-00003 | B4: SO-2025-0003 | C4: 45672 | D4: C004 | E4: =SUMIFS(Sales!$L$2:$L$759,Sales!$B$2:$B$759,B4) -> 30259400 | F4: 30 | G4: =C4+F4 -> 45702 | H4: 45726 | I4: 30259400 | J4: =ROUND(E4-I4,0) -> 0 | K4: =IF(J4<=0,"Paid",IF(G4<Settings!$B$2,"Overdue","Open")) -> Paid | L4: =IF(J4>0,MAX(0,Settings!$B$2-G4),0) -> 0 | M4: =IF(J4<=0,"Paid",IF(L4=0,"Current",IF(L4<=30,"1-30",IF(L4<=60,"31-60",IF(L4<=90,"61-90","90+"))))) -> Paid
A5: INV-00004 | B5: SO-2025-0004 | C5: 45679 | D5: C009 | E5: =SUMIFS(Sales!$L$2:$L$759,Sales!$B$2:$B$759,B5) -> 16632600 | F5: 45 | G5: =C5+F5 -> 45724 | H5: 45754 | I5: 16632600 | J5: =ROUND(E5-I5,0) -> 0 | K5: =IF(J5<=0,"Paid",IF(G5<Settings!$B$2,"Overdue","Open")) -> Paid | L5: =IF(J5>0,MAX(0,Settings!$B$2-G5),0) -> 0 | M5: =IF(J5<=0,"Paid",IF(L5=0,"Current",IF(L5<=30,"1-30",IF(L5<=60,"31-60",IF(L5<=90,"61-90","90+"))))) -> Paid
A6: INV-00005 | B6: SO-2025-0005 | C6: 45676 | D6: C002 | E6: =SUMIFS(Sales!$L$2:$L$759,Sales!$B$2:$B$759,B6) -> 2754000 | F6: 45 | G6: =C6+F6 -> 45721 | H6: 45685 | I6: 2754000 | J6: =ROUND(E6-I6,0) -> 0 | K6: =IF(J6<=0,"Paid",IF(G6<Settings!$B$2,"Overdue","Open")) -> Paid | L6: =IF(J6>0,MAX(0,Settings!$B$2-G6),0) -> 0 | M6: =IF(J6<=0,"Paid",IF(L6=0,"Current",IF(L6<=30,"1-30",IF(L6<=60,"31-60",IF(L6<=90,"61-90","90+"))))) -> Paid
A7: INV-00006 | B7: SO-2025-0006 | C7: 45682 | D7: C002 | E7: =SUMIFS(Sales!$L$2:$L$759,Sales!$B$2:$B$759,B7) -> 16087600 | F7: 45 | G7: =C7+F7 -> 45727 | H7: 45725 | I7: 16087600 | J7: =ROUND(E7-I7,0) -> 0 | K7: =IF(J7<=0,"Paid",IF(G7<Settings!$B$2,"Overdue","Open")) -> Paid | L7: =IF(J7>0,MAX(0,Settings!$B$2-G7),0) -> 0 | M7: =IF(J7<=0,"Paid",IF(L7=0,"Current",IF(L7<=30,"1-30",IF(L7<=60,"31-60",IF(L7<=90,"61-90","90+"))))) -> Paid
A8: INV-00007 | B8: SO-2025-0007 | C8: 45675 | D8: C008 | E8: =SUMIFS(Sales!$L$2:$L$759,Sales!$B$2:$B$759,B8) -> 9421700 | F8: 60 | G8: =C8+F8 -> 45735 | H8: 45750 | I8: 9421700 | J8: =ROUND(E8-I8,0) -> 0 | K8: =IF(J8<=0,"Paid",IF(G8<Settings!$B$2,"Overdue","Open")) -> Paid | L8: =IF(J8>0,MAX(0,Settings!$B$2-G8),0) -> 0 | M8: =IF(J8<=0,"Paid",IF(L8=0,"Current",IF(L8<=30,"1-30",IF(L8<=60,"31-60",IF(L8<=90,"61-90","90+"))))) -> Paid
A9: INV-00008 | B9: SO-2025-0008 | C9: 45687 | D9: C001 | E9: =SUMIFS(Sales!$L$2:$L$759,Sales!$B$2:$B$759,B9) -> 3728100 | F9: 30 | G9: =C9+F9 -> 45717 | H9: 45736 | I9: 3728100 | J9: =ROUND(E9-I9,0) -> 0 | K9: =IF(J9<=0,"Paid",IF(G9<Settings!$B$2,"Overdue","Open")) -> Paid | L9: =IF(J9>0,MAX(0,Settings!$B$2-G9),0) -> 0 | M9: =IF(J9<=0,"Paid",IF(L9=0,"Current",IF(L9<=30,"1-30",IF(L9<=60,"31-60",IF(L9<=90,"61-90","90+"))))) -> Paid
A10: INV-00009 | B10: SO-2025-0009 | C10: 45686 | D10: C001 | E10: =SUMIFS(Sales!$L$2:$L$759,Sales!$B$2:$B$759,B10) -> 30514600 | F10: 30 | G10: =C10+F10 -> 45716 | H10: 45717 | I10: 30514600 | J10: =ROUND(E10-I10,0) -> 0 | K10: =IF(J10<=0,"Paid",IF(G10<Settings!$B$2,"Overdue","Open")) -> Paid | L10: =IF(J10>0,MAX(0,Settings!$B$2-G10),0) -> 0 | M10: =IF(J10<=0,"Paid",IF(L10=0,"Current",IF(L10<=30,"1-30",IF(L10<=60,"31-60",IF(L10<=90,"61-90","90+"))))) -> Paid
A11: INV-00010 | B11: SO-2025-0010 | C11: 45681 | D11: C002 | E11: =SUMIFS(Sales!$L$2:$L$759,Sales!$B$2:$B$759,B11) -> 4660600 | F11: 45 | G11: =C11+F11 -> 45726 | H11: 45738 | I11: 4660600 | J11: =ROUND(E11-I11,0) -> 0 | K11: =IF(J11<=0,"Paid",IF(G11<Settings!$B$2,"Overdue","Open")) -> Paid | L11: =IF(J11>0,MAX(0,Settings!$B$2-G11),0) -> 0 | M11: =IF(J11<=0,"Paid",IF(L11=0,"Current",IF(L11<=30,"1-30",IF(L11<=60,"31-60",IF(L11<=90,"61-90","90+"))))) -> Paid
A12: INV-00011 | B12: SO-2025-0011 | C12: 45695 | D12: C004 | E12: =SUMIFS(Sales!$L$2:$L$759,Sales!$B$2:$B$759,B12) -> 4933700 | F12: 30 | G12: =C12+F12 -> 45725 | H12: 45741 | I12: 4933700 | J12: =ROUND(E12-I12,0) -> 0 | K12: =IF(J12<=0,"Paid",IF(G12<Settings!$B$2,"Overdue","Open")) -> Paid | L12: =IF(J12>0,MAX(0,Settings!$B$2-G12),0) -> 0 | M12: =IF(J12<=0,"Paid",IF(L12=0,"Current",IF(L12<=30,"1-30",IF(L12<=60,"31-60",IF(L12<=90,"61-90","90+"))))) -> Paid
A13: INV-00012 | B13: SO-2025-0012 | C13: 45687 | D13: C014 | E13: =SUMIFS(Sales!$L$2:$L$759,Sales!$B$2:$B$759,B13) -> 38292800 | F13: 45 | G13: =C13+F13 -> 45732 | H13: 45746 | I13: 38292800 | J13: =ROUND(E13-I13,0) -> 0 | K13: =IF(J13<=0,"Paid",IF(G13<Settings!$B$2,"Overdue","Open")) -> Paid | L13: =IF(J13>0,MAX(0,Settings!$B$2-G13),0) -> 0 | M13: =IF(J13<=0,"Paid",IF(L13=0,"Current",IF(L13<=30,"1-30",IF(L13<=60,"31-60",IF(L13<=90,"61-90","90+"))))) -> Paid
A14: INV-00013 | B14: SO-2025-0013 | C14: 45683 | D14: C010 | E14: =SUMIFS(Sales!$L$2:$L$759,Sales!$B$2:$B$759,B14) -> 7230292 | F14: 30 | G14: =C14+F14 -> 45713 | H14: 45746 | I14: 7230292 | J14: =ROUND(E14-I14,0) -> 0 | K14: =IF(J14<=0,"Paid",IF(G14<Settings!$B$2,"Overdue","Open")) -> Paid | L14: =IF(J14>0,MAX(0,Settings!$B$2-G14),0) -> 0 | M14: =IF(J14<=0,"Paid",IF(L14=0,"Current",IF(L14<=30,"1-30",IF(L14<=60,"31-60",IF(L14<=90,"61-90","90+"))))) -> Paid
A15: INV-00014 | B15: SO-2025-0014 | C15: 45694 | D15: C007 | E15: =SUMIFS(Sales!$L$2:$L$759,Sales!$B$2:$B$759,B15) -> 18151800 | F15: 30 | G15: =C15+F15 -> 45724 | I15: 0 | J15: =ROUND(E15-I15,0) -> 18151800 | K15: =IF(J15<=0,"Paid",IF(G15<Settings!$B$2,"Overdue","Open")) -> Overdue | L15: =IF(J15>0,MAX(0,Settings!$B$2-G15),0) -> 596 | M15: =IF(J15<=0,"Paid",IF(L15=0,"Current",IF(L15<=30,"1-30",IF(L15<=60,"31-60",IF(L15<=90,"61-90","90+"))))) -> 90+
A16: INV-00015 | B16: SO-2025-0015 | C16: 45714 | D16: C004 | E16: =SUMIFS(Sales!$L$2:$L$759,Sales!$B$2:$B$759,B16) -> 990660 | F16: 30 | G16: =C16+F16 -> 45744 | H16: 45763 | I16: 990660 | J16: =ROUND(E16-I16,0) -> 0 | K16: =IF(J16<=0,"Paid",IF(G16<Settings!$B$2,"Overdue","Open")) -> Paid | L16: =IF(J16>0,MAX(0,Settings!$B$2-G16),0) -> 0 | M16: =IF(J16<=0,"Paid",IF(L16=0,"Current",IF(L16<=30,"1-30",IF(L16<=60,"31-60",IF(L16<=90,"61-90","90+"))))) -> Paid
A17: INV-00016 | B17: SO-2025-0016 | C17: 45712 | D17: C007 | E17: =SUMIFS(Sales!$L$2:$L$759,Sales!$B$2:$B$759,B17) -> 11152000 | F17: 30 | G17: =C17+F17 -> 45742 | H17: 45754 | I17: 11152000 | J17: =ROUND(E17-I17,0) -> 0 | K17: =IF(J17<=0,"Paid",IF(G17<Settings!$B$2,"Overdue","Open")) -> Paid | L17: =IF(J17>0,MAX(0,Settings!$B$2-G17),0) -> 0 | M17: =IF(J17<=0,"Paid",IF(L17=0,"Current",IF(L17<=30,"1-30",IF(L17<=60,"31-60",IF(L17<=90,"61-90","90+"))))) -> Paid
A18: INV-00017 | B18: SO-2025-0017 | C18: 45717 | D18: C001 | E18: =SUMIFS(Sales!$L$2:$L$759,Sales!$B$2:$B$759,B18) -> 2389200 | F18: 30 | G18: =C18+F18 -> 45747 | H18: 45782 | I18: 2389200 | J18: =ROUND(E18-I18,0) -> 0 | K18: =IF(J18<=0,"Paid",IF(G18<Settings!$B$2,"Overdue","Open")) -> Paid | L18: =IF(J18>0,MAX(0,Settings!$B$2-G18),0) -> 0 | M18: =IF(J18<=0,"Paid",IF(L18=0,"Current",IF(L18<=30,"1-30",IF(L18<=60,"31-60",IF(L18<=90,"61-90","90+"))))) -> Paid
A19: INV-00018 | B19: SO-2025-0018 | C19: 45719 | D19: C014 | E19: =SUMIFS(Sales!$L$2:$L$759,Sales!$B$2:$B$759,B19) -> 39721435 | F19: 45 | G19: =C19+F19 -> 45764 | H19: 45780 | I19: 39721435 | J19: =ROUND(E19-I19,0) -> 0 | K19: =IF(J19<=0,"Paid",IF(G19<Settings!$B$2,"Overdue","Open")) -> Paid | L19: =IF(J19>0,MAX(0,Settings!$B$2-G19),0) -> 0 | M19: =IF(J19<=0,"Paid",IF(L19=0,"Current",IF(L19<=30,"1-30",IF(L19<=60,"31-60",IF(L19<=90,"61-90","90+"))))) -> Paid
A20: INV-00019 | B20: SO-2025-0019 | C20: 45710 | D20: C013 | E20: =SUMIFS(Sales!$L$2:$L$759,Sales!$B$2:$B$759,B20) -> 39993000 | F20: 30 | G20: =C20+F20 -> 45740 | H20: 45749 | I20: 39993000 | J20: =ROUND(E20-I20,0) -> 0 | K20: =IF(J20<=0,"Paid",IF(G20<Settings!$B$2,"Overdue","Open")) -> Paid | L20: =IF(J20>0,MAX(0,Settings!$B$2-G20),0) -> 0 | M20: =IF(J20<=0,"Paid",IF(L20=0,"Current",IF(L20<=30,"1-30",IF(L20<=60,"31-60",IF(L20<=90,"61-90","90+"))))) -> Paid
A21: INV-00020 | B21: SO-2025-0020 | C21: 45715 | D21: C003 | E21: =SUMIFS(Sales!$L$2:$L$759,Sales!$B$2:$B$759,B21) -> 29517400 | F21: 45 | G21: =C21+F21 -> 45760 | H21: 45772 | I21: 29517400 | J21: =ROUND(E21-I21,0) -> 0 | K21: =IF(J21<=0,"Paid",IF(G21<Settings!$B$2,"Overdue","Open")) -> Paid | L21: =IF(J21>0,MAX(0,Settings!$B$2-G21),0) -> 0 | M21: =IF(J21<=0,"Paid",IF(L21=0,"Current",IF(L21<=30,"1-30",IF(L21<=60,"31-60",IF(L21<=90,"61-90","90+"))))) -> Paid
A22: INV-00021 | B22: SO-2025-0021 | C22: 45729 | D22: C006 | E22: =SUMIFS(Sales!$L$2:$L$759,Sales!$B$2:$B$759,B22) -> 970400 | F22: 45 | G22: =C22+F22 -> 45774 | H22: 45799 | I22: 970400 | J22: =ROUND(E22-I22,0) -> 0 | K22: =IF(J22<=0,"Paid",IF(G22<Settings!$B$2,"Overdue","Open")) -> Paid | L22: =IF(J22>0,MAX(0,Settings!$B$2-G22),0) -> 0 | M22: =IF(J22<=0,"Paid",IF(L22=0,"Current",IF(L22<=30,"1-30",IF(L22<=60,"31-60",IF(L22<=90,"61-90","90+"))))) -> Paid
A23: INV-00022 | B23: SO-2025-0022 | C23: 45730 | D23: C009 | E23: =SUMIFS(Sales!$L$2:$L$759,Sales!$B$2:$B$759,B23) -> 1605600 | F23: 45 | G23: =C23+F23 -> 45775 | H23: 45825 | I23: 1605600 | J23: =ROUND(E23-I23,0) -> 0 | K23: =IF(J23<=0,"Paid",IF(G23<Settings!$B$2,"Overdue","Open")) -> Paid | L23: =IF(J23>0,MAX(0,Settings!$B$2-G23),0) -> 0 | M23: =IF(J23<=0,"Paid",IF(L23=0,"Current",IF(L23<=30,"1-30",IF(L23<=60,"31-60",IF(L23<=90,"61-90","90+"))))) -> Paid
A24: INV-00023 | B24: SO-2025-0023 | C24: 45733 | D24: C001 | E24: =SUMIFS(Sales!$L$2:$L$759,Sales!$B$2:$B$759,B24) -> 32476600 | F24: 30 | G24: =C24+F24 -> 45763 | H24: 45784 | I24: 27141885 | J24: =ROUND(E24-I24,0) -> 5334715 | K24: =IF(J24<=0,"Paid",IF(G24<Settings!$B$2,"Overdue","Open")) -> Overdue | L24: =IF(J24>0,MAX(0,Settings!$B$2-G24),0) -> 557 | M24: =IF(J24<=0,"Paid",IF(L24=0,"Current",IF(L24<=30,"1-30",IF(L24<=60,"31-60",IF(L24<=90,"61-90","90+"))))) -> 90+
A25: INV-00024 | B25: SO-2025-0024 | C25: 45735 | D25: C010 | E25: =SUMIFS(Sales!$L$2:$L$759,Sales!$B$2:$B$759,B25) -> 3249900 | F25: 30 | G25: =C25+F25 -> 45765 | H25: 45807 | I25: 3249900 | J25: =ROUND(E25-I25,0) -> 0 | K25: =IF(J25<=0,"Paid",IF(G25<Settings!$B$2,"Overdue","Open")) -> Paid | L25: =IF(J25>0,MAX(0,Settings!$B$2-G25),0) -> 0 | M25: =IF(J25<=0,"Paid",IF(L25=0,"Current",IF(L25<=30,"1-30",IF(L25<=60,"31-60",IF(L25<=90,"61-90","90+"))))) -> Paid
A26: INV-00025 | B26: SO-2025-0025 | C26: 45742 | D26: C004 | E26: =SUMIFS(Sales!$L$2:$L$759,Sales!$B$2:$B$759,B26) -> 2967600 | F26: 30 | G26: =C26+F26 -> 45772 | H26: 45797 | I26: 2967600 | J26: =ROUND(E26-I26,0) -> 0 | K26: =IF(J26<=0,"Paid",IF(G26<Settings!$B$2,"Overdue","Open")) -> Paid | L26: =IF(J26>0,MAX(0,Settings!$B$2-G26),0) -> 0 | M26: =IF(J26<=0,"Paid",IF(L26=0,"Current",IF(L26<=30,"1-30",IF(L26<=60,"31-60",IF(L26<=90,"61-90","90+"))))) -> Paid
A27: INV-00026 | B27: SO-2025-0026 | C27: 45744 | D27: C007 | E27: =SUMIFS(Sales!$L$2:$L$759,Sales!$B$2:$B$759,B27) -> 1314200 | F27: 30 | G27: =C27+F27 -> 45774 | H27: 45777 | I27: 1314200 | J27: =ROUND(E27-I27,0) -> 0 | K27: =IF(J27<=0,"Paid",IF(G27<Settings!$B$2,"Overdue","Open")) -> Paid | L27: =IF(J27>0,MAX(0,Settings!$B$2-G27),0) -> 0 | M27: =IF(J27<=0,"Paid",IF(L27=0,"Current",IF(L27<=30,"1-30",IF(L27<=60,"31-60",IF(L27<=90,"61-90","90+"))))) -> Paid
... A42: INV-00041 | B42: SO-2025-0041 | C42: 45755 | D42: C004 | E42: =SUMIFS(Sales!$L$2:$L$759,Sales!$B$2:$B$759,B42) -> 9068700 | F42: 30 | G42: =C42+F42 -> 45785 | H42: 45811 | I42: 9068700 | J42: =ROUND(E42-I42,0) -> 0 | K42: =IF(J42<=0,"Paid",IF(G42<Settings!$B$2,"Overdue","Open")) -> Paid | L42: =IF(J42>0,MAX(0,Settings!$B$2-G42),0) -> 0 | M42: =IF(J42<=0,"Paid",IF(L42=0,"Current",IF(L42<=30,"1-30",IF(L42<=60,"31-60",IF(L42<=90,"61-90","90+"))))) -> Paid
A43: INV-00042 | B43: SO-2025-0042 | C43: 45771 | D43: C002 | E43: =SUMIFS(Sales!$L$2:$L$759,Sales!$B$2:$B$759,B43) -> 51779116 | F43: 45 | G43: =C43+F43 -> 45816 | I43: 0 | J43: =ROUND(E43-I43,0) -> 51779116 | K43: =IF(J43<=0,"Paid",IF(G43<Settings!$B$2,"Overdue","Open")) -> Overdue | L43: =IF(J43>0,MAX(0,Settings!$B$2-G43),0) -> 504 | M43: =IF(J43<=0,"Paid",IF(L43=0,"Current",IF(L43<=30,"1-30",IF(L43<=60,"31-60",IF(L43<=90,"61-90","90+"))))) -> 90+
A44: INV-00043 | B44: SO-2025-0043 | C44: 45770 | D44: C002 | E44: =SUMIFS(Sales!$L$2:$L$759,Sales!$B$2:$B$759,B44) -> 3399700 | F44: 45 | G44: =C44+F44 -> 45815 | H44: 45797 | I44: 1575278 | J44: =ROUND(E44-I44,0) -> 1824422 | K44: =IF(J44<=0,"Paid",IF(G44<Settings!$B$2,"Overdue","Open")) -> Overdue | L44: =IF(J44>0,MAX(0,Settings!$B$2-G44),0) -> 505 | M44: =IF(J44<=0,"Paid",IF(L44=0,"Current",IF(L44<=30,"1-30",IF(L44<=60,"31-60",IF(L44<=90,"61-90","90+"))))) -> 90+
A45: INV-00044 | B45: SO-2025-0044 | C45: 45768 | D45: C002 | E45: =SUMIFS(Sales!$L$2:$L$759,Sales!$B$2:$B$759,B45) -> 1738800 | F45: 45 | G45: =C45+F45 -> 45813 | H45: 45808 | I45: 1738800 | J45: =ROUND(E45-I45,0) -> 0 | K45: =IF(J45<=0,"Paid",IF(G45<Settings!$B$2,"Overdue","Open")) -> Paid | L45: =IF(J45>0,MAX(0,Settings!$B$2-G45),0) -> 0 | M45: =IF(J45<=0,"Paid",IF(L45=0,"Current",IF(L45<=30,"1-30",IF(L45<=60,"31-60",IF(L45<=90,"61-90","90+"))))) -> Paid
A46: INV-00045 | B46: SO-2025-0045 | C46: 45776 | D46: C008 | E46: =SUMIFS(Sales!$L$2:$L$759,Sales!$B$2:$B$759,B46) -> 6473200 | F46: 60 | G46: =C46+F46 -> 45836 | H46: 45874 | I46: 6473200 | J46: =ROUND(E46-I46,0) -> 0 | K46: =IF(J46<=0,"Paid",IF(G46<Settings!$B$2,"Overdue","Open")) -> Paid | L46: =IF(J46>0,MAX(0,Settings!$B$2-G46),0) -> 0 | M46: =IF(J46<=0,"Paid",IF(L46=0,"Current",IF(L46<=30,"1-30",IF(L46<=60,"31-60",IF(L46<=90,"61-90","90+"))))) -> Paid
A47: INV-00046 | B47: SO-2025-0046 | C47: 45771 | D47: C010 | E47: =SUMIFS(Sales!$L$2:$L$759,Sales!$B$2:$B$759,B47) -> 5288800 | F47: 30 | G47: =C47+F47 -> 45801 | H47: 45826 | I47: 5288800 | J47: =ROUND(E47-I47,0) -> 0 | K47: =IF(J47<=0,"Paid",IF(G47<Settings!$B$2,"Overdue","Open")) -> Paid | L47: =IF(J47>0,MAX(0,Settings!$B$2-G47),0) -> 0 | M47: =IF(J47<=0,"Paid",IF(L47=0,"Current",IF(L47<=30,"1-30",IF(L47<=60,"31-60",IF(L47<=90,"61-90","90+"))))) -> Paid
A48: INV-00047 | B48: SO-2025-0047 | C48: 45781 | D48: C004 | E48: =SUMIFS(Sales!$L$2:$L$759,Sales!$B$2:$B$759,B48) -> 53926400 | F48: 30 | G48: =C48+F48 -> 45811 | H48: 45825 | I48: 53926400 | J48: =ROUND(E48-I48,0) -> 0 | K48: =IF(J48<=0,"Paid",IF(G48<Settings!$B$2,"Overdue","Open")) -> Paid | L48: =IF(J48>0,MAX(0,Settings!$B$2-G48),0) -> 0 | M48: =IF(J48<=0,"Paid",IF(L48=0,"Current",IF(L48<=30,"1-30",IF(L48<=60,"31-60",IF(L48<=90,"61-90","90+"))))) -> Paid
A49: INV-00048 | B49: SO-2025-0048 | C49: 45786 | D49: C002 | E49: =SUMIFS(Sales!$L$2:$L$759,Sales!$B$2:$B$759,B49) -> 5709600 | F49: 45 | G49: =C49+F49 -> 45831 | H49: 45822 | I49: 5709600 | J49: =ROUND(E49-I49,0) -> 0 | K49: =IF(J49<=0,"Paid",IF(G49<Settings!$B$2,"Overdue","Open")) -> Paid | L49: =IF(J49>0,MAX(0,Settings!$B$2-G49),0) -> 0 | M49: =IF(J49<=0,"Paid",IF(L49=0,"Current",IF(L49<=30,"1-30",IF(L49<=60,"31-60",IF(L49<=90,"61-90","90+"))))) -> Paid
